Workbook
Name Cap: Inputs!$B$4
Name Bonus: Inputs!$B$5
Name Barrier: Inputs!$B$6
Name Ratio: Inputs!$B$7
Name IssueDate: Inputs!$B$8
Name MatDate: Inputs!$B$9
Name AnnualDiv: Inputs!$B$11
Name RefSpot: Inputs!$B$12
Name q: Inputs!$B$13
Name EWMALam: Inputs!$B$14
Name dS: Inputs!$B$16
Name dSig: Inputs!$B$17
Name dT: Inputs!$B$18
Name dR: Inputs!$B$19
Name S0_d: Inputs!$B$21
Name K_d: Inputs!$B$22
Name KCap_d: Inputs!$B$23
Name T_d: Inputs!$B$24
Name Sig_d: Inputs!$B$25
Name svb0: Inputs!$B$27
Name svb1: Inputs!$B$28
Name svb2: Inputs!$B$29
Name svb3: Inputs!$B$30
Name svt1: Inputs!$B$31
Name svt2: Inputs!$B$32
Name W0_mc: Inputs!$B$34
Name T_mc: Inputs!$B$35
Name NSteps: Inputs!$B$36
Name NPaths: Inputs!$B$37
Name MCseed: Inputs!$B$38
Name S0_mc: Inputs!$B$39
Name mu_mc: Inputs!$B$40
Name Sig_mc: Inputs!$B$41
Name r_mc: Inputs!$B$42
Name q_mc: Inputs!$B$43

Sheet Cover
A1: B401 -- Continuous-Time Derivatives Pricing
A2: Unified Workbook: Parts 1, 2 and 3 (Tasks I through XI)
A3: Student: DU2076 | Date built: 2026-06-20 | Course: B401 Summer 2026
A5: Field | B5: Value | C5: Source
A6: Product name | B6: DZ BANK Bonus/Protection Cert on Rheinmetall | C6: [C] KID DE000DU20767
A7: WKN | B7: DU2076 | C7: [C]
A8: Issuer | B8: DZ BANK AG | C8: [C]
A9: Underlying | B9: Rheinmetall AG (RHM.DE) | C9: [C]
A10: Barrier | B10: 1,050 EUR | C10: [C] Barriere
A11: Cap / Bonus | B11: 2,000 EUR | C11: [C] Hoechstbetrag
A12: Issue date | B12: 2025-09-04 | C12: [C] Emissionstag
A13: Maturity date | B13: 2027-06-18 | C13: [C] Bewertungstag
A14: Pricing engine | B14: N=200 CRR binomial tree (Python, canonical) | C14: [P]
A15: Greeks / Rep. port. | B15: Rubinstein-Reiner (1991) closed-form (cross-check) | C15: [P]
A17: Sourcing legend
A18: [C] Contractual | B18: DZ BANK KID DE000DU20767 dated 12.06.2026
A19: [M] Market data | B19: Yahoo Finance (yfinance, RHM.DE) / onvista.de (cert prices)
A20: [E] ECB source | B20: ECB AAA sovereign yield-curve dataset, downloaded 2026-06-15
A21: [P] Model param | B21: Stated assumption, derivation shown in workbook
A23: Sheet index
A24: Tab | B24: Purpose
A25: Cover | B25: Product identity, methodology, sheet index, sourcing legend
A26: Inputs | B26: Named-range constants: contractual terms, model params, Part 1 design
A27: Data_Stock | B27: RHM.DE daily closes + EWMA vol (183 trading days, static)
A28: Data_Cert | B28: DU2076 certificate daily market prices (183 rows, static)
A29: Data_Svensson | B29: ECB AAA Svensson params per trading day (183 rows, static)
A30: MC_Paths | B30: Pre-computed GBM paths: S_term, S_half, S_term_shock (50,000 rows)
A31: P1_Tasks_I_IV | B31: Investor profile, product design, payoff table, market size
A32: P2_TaskV_Val | B32: Daily model vs market valuation (183 rows) + error metrics
A33: P2_TaskVI_Greeks | B33: Greeks cross-section (100 S values) + reference-point summary
A34: P2_TaskVII_Rep | B34: Daily replicating portfolio (183 rows) + equity fraction vs S
A35: P3_TaskVIII | B35: MC unhedged performance: Mean, Std, Sharpe, VaR, CVaR
... A39: CrossCheck | B39: Reconciliation: all 27 targets vs notebook, pass/fail flags
A41: IMPORTANT: Workbook calculation is set to MANUAL. Press Ctrl+Alt+F9 (Windows) or Cmd+Option+F9 (Mac) after opening to recalculate all formulas.

Sheet Inputs
A1: Inputs -- Named Ranges and Model Parameters
A2: Parameter | B2: Value | C2: Unit | D2: Source | E2: Description
A3: --- Contractual terms (KID DE000DU20767) ---
A4: Cap | B4: 2000 | C4: EUR | D4: [C] | E4: Hoechstbetrag -- maximum redemption
A5: Bonus | B5: 2000 | C5: EUR | D5: [C] | E5: Bonusbetrag -- bonus level
A6: Barrier | B6: 1050 | C6: EUR | D6: [C] | E6: Barriere -- knock-in barrier
A7: Ratio | B7: 1 | D7: [C] | E7: Bezugsverhaeltnis -- participation ratio
A8: IssueDate | B8: 2025-09-04 | D8: [C] | E8: Emissionstag -- issue / first trading date
A9: MatDate | B9: 2027-06-18 | D9: [C] | E9: Bewertungstag -- final valuation date
A10: --- Market-derived inputs ---
A11: AnnualDiv | B11: 7.2 | C11: EUR | D11: [M] | E11: Rheinmetall FY2024 DPS (investor relations)
A12: RefSpot | B12: 1207 | C12: EUR | D12: [M] | E12: Last RHM.DE close in valuation window (2026-06-01)
A13: q | B13: 0.006 | D13: [M] | E13: Continuous dividend yield = 7.20/1207.00
A14: EWMALam | B14: 0.94 | D14: [P] | E14: RiskMetrics standard EWMA lambda
A15: --- FD bump sizes ---
A16: dS | B16: 0.01 | D16: [P] | E16: 1% central bump on S (Delta/Gamma)
A17: dSig | B17: 0.02 | D17: [P] | E17: 2% central bump on sigma (Vega)
A18: dT | B18: 0.003968254 | C18: yr | D18: [P] | E18: 1 trading day in years (Theta step)
A19: dR | B19: 0.0001 | D19: [P] | E19: 1 bp central bump on r (Rho)
A20: --- Part 1 design parameters ---
A21: S0_d | B21: 1207 | C21: EUR | D21: [P] | E21: RefSpot on design date 2026-06-01
A22: K_d | B22: 1207 | C22: EUR | D22: [P] | E22: ATM strike = S0_d
A23: KCap_d | B23: 1569.1 | C23: EUR | D23: [P] | E23: Cap strike = 1.30 * S0_d
A24: T_d | B24: 3 | C24: yr | D24: [P] | E24: Product maturity (years)
A25: Sig_d | B25: 0.5417 | D25: [P] | E25: EWMA vol at design date (2026-06-01)
A26: --- Svensson params (ECB AAA, 2026-06-01) ---
A27: svb0 | B27: 1.330382 | D27: [E] | E27: Beta0
A28: svb1 | B28: 0.700052 | D28: [E] | E28: Beta1
A29: svb2 | B29: 1.816755 | D29: [E] | E29: Beta2
A30: svb3 | B30: 7.130184 | D30: [E] | E30: Beta3
A31: svt1 | B31: 0.966763 | D31: [E] | E31: Tau1
A32: svt2 | B32: 15.839369 | D32: [E] | E32: Tau2
A33: --- Part 3 Monte Carlo parameters ---
A34: W0_mc | B34: 10000 | C34: EUR | D34: [P] | E34: Initial capital
A35: T_mc | B35: 1 | C35: yr | D35: [P] | E35: Investment horizon
A36: NSteps | B36: 252 | D36: [P] | E36: GBM time steps per year
A37: NPaths | B37: 50000 | D37: [P] | E37: Monte Carlo paths
A38: MCseed | B38: 2026 | D38: [P] | E38: numpy random seed
A39: S0_mc | B39: 1207 | C39: EUR | D39: [P] | E39: GBM initial stock price = RefSpot
A40: mu_mc | B40: 0.5405 | D40: [P] | E40: Annualized historical mean log return (Jan2023-Jun2026)
...

Sheet Data_Stock
A1: Data_Stock -- RHM.DE daily closes and EWMA volatility (183 trading days)
A2: [M] Source: Yahoo Finance yfinance RHM.DE auto-adjusted close. EWMA vol: lambda=0.94 RiskMetrics, annualized * sqrt(252). Window: 2025-09-04 to 2026-06-01.
A3: Date | B3: RHM_Spot_EUR | C3: EWMA_Vol_pct
A4: 45904 | B4: 1707.93 | C4: 0.39
A5: 45905 | B5: 1727.24 | C5: 0.38
A6: 45908 | B6: 1773.27 | C6: 0.383
A7: 45909 | B7: 1761.39 | C7: 0.372
A8: 45910 | B8: 1819.31 | C8: 0.382
A9: 45911 | B9: 1861.89 | C9: 0.381
A10: 45912 | B10: 1877.73 | C10: 0.371
A11: 45915 | B11: 1930.7 | C11: 0.376
A12: 45916 | B12: 1882.19 | C12: 0.377
A13: 45917 | B13: 1869.81 | C13: 0.367
A14: 45918 | B14: 1900.5 | C14: 0.361
A15: 45919 | B15: 1908.92 | C15: 0.351
... A186: 46174 | B186: 1207 | C186: 0.542

Sheet Data_Cert
A1: Data_Cert -- DU2076 daily market prices (183 trading days)
A2: [M] Source: onvista.de -- closing prices for DZ BANK certificate DE000DU20767.
A3: Date | B3: Market_Price_EUR
A4: 45904 | B4: 1635.75
A5: 45905 | B5: 1648.28
A6: 45908 | B6: 1675.51
A7: 45909 | B7: 1671.59
A8: 45910 | B8: 1699.14
A9: 45911 | B9: 1721.63
A10: 45912 | B10: 1713.91
A11: 45915 | B11: 1735.5
A12: 45916 | B12: 1728.41
A13: 45917 | B13: 1699.94
A14: 45918 | B14: 1708.18
A15: 45919 | B15: 1711.35
... A186: 46174 | B186: 1236.07

Sheet Data_Svensson
A1: Data_Svensson -- ECB AAA Svensson parameters per trading day (183 rows)
A2: [E] Source: ECB Data Portal, AAA sovereign yield curve, downloaded 2026-06-15. Parameters forward-filled for non-ECB-publication dates.
A3: Date | B3: b0 | C3: b1 | D3: b2 | E3: b3 | F3: tau1 | G3: tau2 | H3: T_rem_yr | I3: r_daily
A4: 45904 | B4: 1.168343 | C4: 0.791456 | D4: -1.558745 | E4: 7.547626 | F4: 2.877366 | G4: 12.757641 | H4: 1.7863014 | I4: 0.019161407
A5: 45905 | B5: 1.167426 | C5: 0.761807 | D5: -1.821262 | E5: 7.664804 | F5: 3.218451 | G5: 12.62628 | H5: 1.7835616 | I5: 0.01893438
A6: 45908 | B6: 1.198176 | C6: 0.752225 | D6: -2.297018 | E6: 7.725683 | F6: 3.438575 | G6: 11.802636 | H6: 1.7753425 | I6: 0.018881794
A7: 45909 | B7: 1.205197 | C7: 0.740409 | D7: -1.677676 | E7: 7.39418 | F7: 3.023955 | G7: 12.832287 | H7: 1.7726027 | I7: 0.018955417
A8: 45910 | B8: 1.202277 | C8: 0.761658 | D8: -1.692318 | E8: 7.386787 | F8: 3.026223 | G8: 12.836812 | H8: 1.769863 | I8: 0.019053388
A9: 45911 | B9: 1.204237 | C9: 0.75691 | D9: -1.615143 | E9: 7.356917 | F9: 3.268254 | G9: 12.889797 | H9: 1.7671233 | I9: 0.019423606
A10: 45912 | B10: 1.199688 | C10: 0.744959 | D10: -1.462092 | E10: 7.352704 | F10: 3.328068 | G10: 12.832385 | H10: 1.7643836 | I10: 0.019649879
A11: 45915 | B11: 1.194697 | C11: 0.750982 | D11: -1.484931 | E11: 7.34158 | F11: 3.322536 | G11: 12.848706 | H11: 1.7561644 | I11: 0.019581829
A12: 45916 | B12: 1.190226 | C12: 0.772804 | D12: -1.510362 | E12: 7.343672 | F12: 3.311418 | G12: 12.845352 | H12: 1.7534247 | I12: 0.019648921
A13: 45917 | B13: 1.203972 | C13: 0.747581 | D13: -1.13154 | E13: 6.979307 | F13: 2.868727 | G13: 13.349989 | H13: 1.7506849 | I13: 0.019507499
A14: 45918 | B14: 1.213035 | C14: 0.746271 | D14: -1.778341 | E14: 7.497673 | F14: 3.456473 | G14: 12.195202 | H14: 1.7479452 | I14: 0.019641012
A15: 45919 | B15: 1.202443 | C15: 0.767881 | D15: -1.45466 | E15: 7.402585 | F15: 3.145587 | G15: 12.699912 | H15: 1.7452055 | I15: 0.019749218
... A186: 46174 | B186: 1.330382 | C186: 0.700052 | D186: 1.816755 | E186: 7.130184 | F186: 0.966763 | G186: 15.839369 | H186: 1.0465753 | I186: 0.024778054

Sheet MC_Paths
A1: MC_Paths -- GBM simulation (numpy seed=2026, N=50000 paths, T*=1y, 252 steps)
A2: [P] Precomputed by build_workbook.py. S0=1207, mu=54.05%, sigma=39.88%, r=3.0681%, q=0.60%, seed=2026. S_term: T=1y price; S_half: T=0.5y price; S_term_shock: -20% at T/2 then continued.
A3: PathID | B3: S_term | C3: S_half | D3: S_term_shock
A4: 1 | B4: 2946.8728 | C4: 1906.8246 | D4: 2357.4982
A5: 2 | B5: 2692.8482 | C5: 1729.6466 | D5: 2154.2786
A6: 3 | B6: 3937.0408 | C6: 1986.7543 | D6: 3149.6327
A7: 4 | B7: 2691.347 | C7: 2458.3094 | D7: 2153.0776
A8: 5 | B8: 1682.2772 | C8: 1232.6847 | D8: 1345.8217
A9: 6 | B9: 2395.1052 | C9: 1467.7354 | D9: 1916.0841
A10: 7 | B10: 1834.5135 | C10: 1628.3854 | D10: 1467.6108
A11: 8 | B11: 1436.8572 | C11: 1773.2325 | D11: 1149.4858
A12: 9 | B12: 6938.9784 | C12: 2706.3416 | D12: 5551.1827
A13: 10 | B13: 1680.7342 | C13: 1112.6218 | D13: 1344.5874
A14: 11 | B14: 3033.0718 | C14: 1628.6637 | D14: 2426.4575
A15: 12 | B15: 1538.0721 | C15: 1145.9945 | D15: 1230.4577
... A50003: 50000 | B50003: 1857.2057 | C50003: 1536.2693 | D50003: 1485.7646

Sheet P1_Tasks_I_IV
A1: Part 1 -- Tasks I through IV
A3: Task I -- Investor Profile
A4: Target investor: aged 40-60 (5-10 years pre-retirement), holding a moderate-risk balanced portfolio, with a 3-year investment horizon. Bullish on European defence rearmament (Rheinmetall / NATO Sondervermogen theme) but unwilling to accept the 54% annualized EWMA volatility of the direct single stock. Prefers guaranteed capital return at maturity with partial upside participation capped at +30%. Suitable for an investor who would otherwise allocate to investment-grade credit (2-3% p.a. yield) and is willing to forgo full equity upside in exchange for principal protection. Source: Notebook Cell 16 / DZ BANK KID investor suitability section.
A7: Task II -- Product Design: Capital Protection Note (CPN)
A8: Replication formula: | B8: CPN = ZCB(S0, r_3y, T) + alpha * [Call(K=S0) - Call(K=Kcap)]
A10: Component | B10: Position | C10: Role
A11: Zero-coupon bond (face = S0_d = 1,207 EUR) | B11: Long (1 unit) | C11: Guarantees 100% capital return at maturity (S0 discounted at r_3y)
A12: ATM European call (K = S0_d = 1,207 EUR) | B12: Long (alpha units) | C12: Provides participation in RHM gains above S0
A13: OTM European call (K = KCap_d = 1,569.10 EUR) | B13: Short (alpha units) | C13: Caps gain at +30%; short premium funds higher alpha participation
A15: Design validation -- live formulas (Inputs named ranges)
A16: Parameter | B16: Formula / Value | C16: Target | D16: Status
A17: r_3y (Svensson, 3y) | B17: =(svb0+svb1*(1-EXP(-T_d/svt1))/(T_d/svt1)+svb2*((1-EXP(-T_d/svt1))/(T_d/svt1)-EXP(-T_d/svt1))+svb3*((1-EXP(-T_d/svt2))/(T_d/svt2)-EXP(-T_d/svt2)))/100 | C17: 2.6192% | D17: =IF(ABS($B$17-0.026192000000000003)<0.01,"PASS","CHECK")
A18: ZCB0 (EUR) | B18: =S0_d*EXP(-$B$17*T_d) | C18: 1,115.79 EUR | D18: =IF(ABS($B$18-1115.79)<0.01,"PASS","CHECK")
A19: Call_ATM (EUR) | B19: =S0_d*EXP(-q*T_d)*NORM.S.DIST((LN(S0_d/K_d)+($B$17-q+0.5*Sig_d^2)*T_d)/(Sig_d*SQRT(T_d)),1)-K_d*EXP(-$B$17*T_d)*NORM.S.DIST(((LN(S0_d/K_d)+($B$17-q+0.5*Sig_d^2)*T_d)/(Sig_d*SQRT(T_d)))-(Sig_d*SQRT(T_d)),1) | C19: 451.04 EUR | D19: =IF(ABS($B$19-451.04)<0.01,"PASS","CHECK")
A20: Call_Cap (EUR) | B20: =S0_d*EXP(-q*T_d)*NORM.S.DIST((LN(S0_d/KCap_d)+($B$17-q+0.5*Sig_d^2)*T_d)/(Sig_d*SQRT(T_d)),1)-KCap_d*EXP(-$B$17*T_d)*NORM.S.DIST(((LN(S0_d/KCap_d)+($B$17-q+0.5*Sig_d^2)*T_d)/(Sig_d*SQRT(T_d)))-(Sig_d*SQRT(T_d)),1) | C20: 353.43 EUR | D20: =IF(ABS($B$20-353.43)<0.01,"PASS","CHECK")
A21: Spread (EUR) | B21: =$B$19-$B$20 | C21: 97.61 EUR | D21: =IF(ABS($B$21-97.61)<0.01,"PASS","CHECK")
A22: Alpha | B22: =(S0_d-$B$18)/$B$21 | C22: 0.9344 | D22: =IF(ABS($B$22-0.9344)<0.01,"PASS","CHECK")
A25: Task III -- Payoff Table (CPN vs direct RHM stock)
A26: S_T / S0_d | B26: S_T (EUR) | C26: CPN payoff (EUR) | D26: vs Direct stock
A27: 0.5 | B27: 603.5 | C27: 1207 | D27: 1
A28: 0.7 | B28: 844.9 | C28: 1207 | D28: 0.42857143
A29: 0.8 | B29: 965.6 | C29: 1207 | D29: 0.25
A30: 0.9 | B30: 1086.3 | C30: 1207 | D30: 0.11111111
A31: 1 | B31: 1207 | C31: 1207 | D31: 0
A32: 1.1 | B32: 1327.7 | C32: 1319.7853 | D32: -0.0059611792
A33: 1.2 | B33: 1448.4 | C33: 1432.5707 | D33: -0.010928829
A34: 1.3 | B34: 1569.1 | C34: 1545.356 | D34: -0.015132224
A35: 1.4 | B35: 1689.8 | C35: 1545.356 | D35: -0.085479922
A36: 1.6 | B36: 1931.2 | C36: 1545.356 | D36: -0.19979493
A38: Payoff: If S_T < S0 => 1,207 EUR (full capital). If S0 <= S_T <= Kcap => 1,207 + 93.44% * (S_T - 1,207). If S_T > Kcap => 1,207 + 93.44% * (1,569.10 - 1,207) = max 1,545 EUR.
A41: Task IV -- German Structured Products Market Size
A42: Item | B42: Value | C42: Source
A43: Total German structured products market | B43: 112 | C43: [P] BSW 2023 slide 13
A44: Kapitalschutz (capital protection) share | B44: 0.038 | C44: [P] BSW 2023 slide 13
A45: Kapitalschutz segment size | B45: 4.256 | C45: [P] derived
A46: Participation notes share (est.) | B46: 0.55 | C46: [P] author estimate
A47: Participation notes market | B47: 2.3408 | C47: [P] derived
A48: Active issues (est.) | B48: 130 | C48: [P] 6 issuers x ~20
A49: Average issue size | B49: 18.006154 | C49: [P] derived

Sheet P2_TaskV_Val
A1: Task V -- Daily Model vs Market Valuation (N=200 CRR Binomial Tree)
A2: Metric | B2: Formula | C2: Value | D2: Target | E2: Tol | F2: Pass/Fail
A3: ME (EUR) | B3: =AVERAGE(F10:F192) | C3: -85.544153 | D3: -85.54 | E3: 0.1 | F3: PASS
A4: MAE (EUR) | B4: =SUMPRODUCT(ABS(F10:F192))/183 | C4: 94.491038 | D4: 94.49 | E4: 0.1 | F4: PASS
A5: RMSE (EUR) | B5: =SQRT(SUMPRODUCT(F10:F192,F10:F192)/183) | C5: 108.91915 | D5: 108.92 | E5: 0.1 | F5: PASS
A6: MAPE (%) | B6: =SUMPRODUCT(ABS(G10:G192))/183*100 | C6: 6.1091803 | D6: 6.11 | E6: 0.05 | F6: PASS
A7: Implied-vol model reference (Python notebook Cell 40): ME = -8.89 EUR, RMSE = 12.37 EUR, MAPE = 0.64%, mean IV = 37.77% vs mean EWMA = 44.27%.
A8: Key findings: (a) EWMA model systematically UNDERPRICES (ME = -85.54 EUR negative throughout valuation window). (b) Mean EWMA vol 44.27% exceeds market-implied vol 37.77% -- EWMA overstates volatility, making calls (and hence cert) appear more expensive than market. (c) Residual error after implied-vol calibration (~9 EUR) reflects issuer bid-ask spread and structuring margin.
A9: Date | B9: RHM_Spot_EUR | C9: EWMA_Vol_pct | D9: Tree_Model_Py | E9: Market_Price_EUR | F9: Error_EUR | G9: Error_pct
A10: 45904 | B10: 1707.93 | C10: 0.39 | D10: 1558.89 | E10: 1635.75 | F10: -76.86 | G10: -0.047
A11: 45905 | B11: 1727.24 | C11: 0.38 | D11: 1571.16 | E11: 1648.28 | F11: -77.12 | G11: -0.0468
A12: 45908 | B12: 1773.27 | C12: 0.383 | D12: 1601.18 | E12: 1675.51 | F12: -74.33 | G12: -0.0444
A13: 45909 | B13: 1761.39 | C13: 0.372 | D13: 1607.28 | E13: 1671.59 | F13: -64.31 | G13: -0.0385
A14: 45910 | B14: 1819.31 | C14: 0.382 | D14: 1628.9 | E14: 1699.14 | F14: -70.24 | G14: -0.0413
A15: 45911 | B15: 1861.89 | C15: 0.381 | D15: 1636.5 | E15: 1721.63 | F15: -85.13 | G15: -0.0494
A16: 45912 | B16: 1877.73 | C16: 0.371 | D16: 1666.15 | E16: 1713.91 | F16: -47.76 | G16: -0.0279
A17: 45915 | B17: 1930.7 | C17: 0.376 | D17: 1688.12 | E17: 1735.5 | F17: -47.38 | G17: -0.0273
A18: 45916 | B18: 1882.19 | C18: 0.377 | D18: 1663.42 | E18: 1728.41 | F18: -64.99 | G18: -0.0376
A19: 45917 | B19: 1869.81 | C19: 0.367 | D19: 1669.48 | E19: 1699.94 | F19: -30.46 | G19: -0.0179
A20: 45918 | B20: 1900.5 | C20: 0.361 | D20: 1694.37 | E20: 1708.18 | F20: -13.81 | G20: -0.0081
A21: 45919 | B21: 1908.92 | C21: 0.351 | D21: 1721 | E21: 1711.35 | F21: 9.65 | G21: 0.0056
... A192: 46174 | B192: 1207 | C192: 0.542 | D192: 1153.79 | E192: 1236.07 | F192: -82.28 | G192: -0.0666

Sheet P2_TaskVI_Greeks
A1: Task VI -- Greeks (Rubinstein-Reiner closed-form, central FD)
A2: Reference input | B2: Value | C2: Unit | D2: Note
A3: S_ref | B3: 1707.93 | C3: EUR | D3: First DU2076 trading-day close (2025-09-04)
A4: sigma | B4: 0.4455 | D4: Median EWMA vol over valuation window (notebook Cell 45)
A5: T_ref | B5: 1.7863014 | C5: yr | D5: Time to maturity from issue date: (2027-06-18 - 2025-09-04)/365
A6: r_ref | B6: =LET(_t,$B$5,_b0,Data_Svensson!$B$4,_b1,Data_Svensson!$C$4,_b2,Data_Svensson!$D$4,_b3,Data_Svensson!$E$4,_t1,Data_Svensson!$F$4,_t2,Data_Svensson!$G$4,(_b0+_b1*(1-EXP(-_t/_t1))/(_t/_t1)+_b2*((1-EXP(-_t/_t1))/(_t/_t1)-EXP(-_t/_t1))+_b3*((1-EXP(-_t/_t2))/(_t/_t2)-EXP(-_t/_t2)))/100) | D6: ECB Svensson r(T_ref) on 2025-09-04 -- LIVE formula
A7: q | B7: 0.006 | D7: Continuous dividend yield
A8: K | B8: 2000 | C8: EUR | D8: Certificate cap = barrier trigger level: Barriere=1050 (but model K=Cap=2000)
A9: H (Barrier) | B9: 1050 | C9: EUR | D9: Down-and-out barrier
A11: Reference-point Greeks (RR closed-form) | E11: Bumped price helper cells (live Excel LET formulas)
A12: Greek | B12: RR Value | C12: Notebook target | D12: Notes | E12: =LET(_S,$B$3,_sig,$B$4,_T,$B$5,_r,$B$6,_K,Cap,_H,Barrier,_q,q,_b,_r-_q,_sqT,_sig*SQRT(_T),_mu,(_b-0.5*_sig^2)/_sig^2,_x1,LN(_S/_K)/_sqT+(1+_mu)*_sqT,_x2,LN(_S/_H)/_sqT+(1+_mu)*_sqT,_y1,LN(_H^2/(_S*_K))/_sqT+(1+_mu)*_sqT,_y2,LN(_H/_S)/_sqT+(1+_mu)*_sqT,_Sbd,_S*EXP(-_q*_T),_Kdr,_K*EXP(-_r*_T),_h2m1,(_H/_S)^(2*(_mu+1)),_h2m,(_H/_S)^(2*_mu),_A1,_Kdr*NORM.S.DIST(_sqT-_x1,1)-_Sbd*NORM.S.DIST(-_x1,1),_A2,_Kdr*NORM.S.DIST(_sqT-_x2,1)-_Sbd*NORM.S.DIST(-_x2,1),_A3,_Kdr*_h2m*NORM.S.DIST(_y1-_sqT,1)-_Sbd*_h2m1*NORM.S.DIST(_y1,1),_A4,_Kdr*_h2m*NORM.S.DIST(_y2-_sqT,1)-_Sbd*_h2m1*NORM.S.DIST(_y2,1),_do,IF(_S<=_H,0,_A1-_A2+_A3-_A4),_cf,_Sbd*NORM.S.DIST(-_x1,1)+_Kdr*NORM.S.DIST(_x1-_sqT,1),IF(_S<=_H,_cf,_do+_cf)) | F12: Price_ref
A13: Price (EUR) | B13: =$E$12 | C13: 1,457.77 EUR | D13: RR vs N=200 tree divergence ~5 EUR expected | E13: =LET(_S,$B$3*(1+dS),_sig,$B$4,_T,$B$5,_r,$B$6,_K,Cap,_H,Barrier,_q,q,_b,_r-_q,_sqT,_sig*SQRT(_T),_mu,(_b-0.5*_sig^2)/_sig^2,_x1,LN(_S/_K)/_sqT+(1+_mu)*_sqT,_x2,LN(_S/_H)/_sqT+(1+_mu)*_sqT,_y1,LN(_H^2/(_S*_K))/_sqT+(1+_mu)*_sqT,_y2,LN(_H/_S)/_sqT+(1+_mu)*_sqT,_Sbd,_S*EXP(-_q*_T),_Kdr,_K*EXP(-_r*_T),_h2m1,(_H/_S)^(2*(_mu+1)),_h2m,(_H/_S)^(2*_mu),_A1,_Kdr*NORM.S.DIST(_sqT-_x1,1)-_Sbd*NORM.S.DIST(-_x1,1),_A2,_Kdr*NORM.S.DIST(_sqT-_x2,1)-_Sbd*NORM.S.DIST(-_x2,1),_A3,_Kdr*_h2m*NORM.S.DIST(_y1-_sqT,1)-_Sbd*_h2m1*NORM.S.DIST(_y1,1),_A4,_Kdr*_h2m*NORM.S.DIST(_y2-_sqT,1)-_Sbd*_h2m1*NORM.S.DIST(_y2,1),_do,IF(_S<=_H,0,_A1-_A2+_A3-_A4),_cf,_Sbd*NORM.S.DIST(-_x1,1)+_Kdr*NORM.S.DIST(_x1-_sqT,1),IF(_S<=_H,_cf,_do+_cf)) | F13: Price_Sp (S +1%)
A14: Delta | B14: =($E$13-$E$14)/(2*dS*$B$3) | C14: 0.2449 | D14: RR vs tree: see divergence note below | E14: =LET(_S,$B$3*(1-dS),_sig,$B$4,_T,$B$5,_r,$B$6,_K,Cap,_H,Barrier,_q,q,_b,_r-_q,_sqT,_sig*SQRT(_T),_mu,(_b-0.5*_sig^2)/_sig^2,_x1,LN(_S/_K)/_sqT+(1+_mu)*_sqT,_x2,LN(_S/_H)/_sqT+(1+_mu)*_sqT,_y1,LN(_H^2/(_S*_K))/_sqT+(1+_mu)*_sqT,_y2,LN(_H/_S)/_sqT+(1+_mu)*_sqT,_Sbd,_S*EXP(-_q*_T),_Kdr,_K*EXP(-_r*_T),_h2m1,(_H/_S)^(2*(_mu+1)),_h2m,(_H/_S)^(2*_mu),_A1,_Kdr*NORM.S.DIST(_sqT-_x1,1)-_Sbd*NORM.S.DIST(-_x1,1),_A2,_Kdr*NORM.S.DIST(_sqT-_x2,1)-_Sbd*NORM.S.DIST(-_x2,1),_A3,_Kdr*_h2m*NORM.S.DIST(_y1-_sqT,1)-_Sbd*_h2m1*NORM.S.DIST(_y1,1),_A4,_Kdr*_h2m*NORM.S.DIST(_y2-_sqT,1)-_Sbd*_h2m1*NORM.S.DIST(_y2,1),_do,IF(_S<=_H,0,_A1-_A2+_A3-_A4),_cf,_Sbd*NORM.S.DIST(-_x1,1)+_Kdr*NORM.S.DIST(_x1-_sqT,1),IF(_S<=_H,_cf,_do+_cf)) | F14: Price_Sm (S -1%)
A15: Gamma | B15: =($E$13-2*$E$12+$E$14)/(dS*$B$3)^2 | C15: ~0 (near 0) | D15: Tree gives near-zero; RR may differ at barrier | E15: =LET(_S,$B$3,_sig,$B$4+dSig,_T,$B$5,_r,$B$6,_K,Cap,_H,Barrier,_q,q,_b,_r-_q,_sqT,_sig*SQRT(_T),_mu,(_b-0.5*_sig^2)/_sig^2,_x1,LN(_S/_K)/_sqT+(1+_mu)*_sqT,_x2,LN(_S/_H)/_sqT+(1+_mu)*_sqT,_y1,LN(_H^2/(_S*_K))/_sqT+(1+_mu)*_sqT,_y2,LN(_H/_S)/_sqT+(1+_mu)*_sqT,_Sbd,_S*EXP(-_q*_T),_Kdr,_K*EXP(-_r*_T),_h2m1,(_H/_S)^(2*(_mu+1)),_h2m,(_H/_S)^(2*_mu),_A1,_Kdr*NORM.S.DIST(_sqT-_x1,1)-_Sbd*NORM.S.DIST(-_x1,1),_A2,_Kdr*NORM.S.DIST(_sqT-_x2,1)-_Sbd*NORM.S.DIST(-_x2,1),_A3,_Kdr*_h2m*NORM.S.DIST(_y1-_sqT,1)-_Sbd*_h2m1*NORM.S.DIST(_y1,1),_A4,_Kdr*_h2m*NORM.S.DIST(_y2-_sqT,1)-_Sbd*_h2m1*NORM.S.DIST(_y2,1),_do,IF(_S<=_H,0,_A1-_A2+_A3-_A4),_cf,_Sbd*NORM.S.DIST(-_x1,1)+_Kdr*NORM.S.DIST(_x1-_sqT,1),IF(_S<=_H,_cf,_do+_cf)) | F15: Price_sigp (sig +2pp)
A16: Vega (per 1% vol) | B16: =($E$15-$E$16)/(2*dSig)/100 | C16: -13.554 | D16: Per 1% absolute change in sigma | E16: =LET(_S,$B$3,_sig,$B$4-dSig,_T,$B$5,_r,$B$6,_K,Cap,_H,Barrier,_q,q,_b,_r-_q,_sqT,_sig*SQRT(_T),_mu,(_b-0.5*_sig^2)/_sig^2,_x1,LN(_S/_K)/_sqT+(1+_mu)*_sqT,_x2,LN(_S/_H)/_sqT+(1+_mu)*_sqT,_y1,LN(_H^2/(_S*_K))/_sqT+(1+_mu)*_sqT,_y2,LN(_H/_S)/_sqT+(1+_mu)*_sqT,_Sbd,_S*EXP(-_q*_T),_Kdr,_K*EXP(-_r*_T),_h2m1,(_H/_S)^(2*(_mu+1)),_h2m,(_H/_S)^(2*_mu),_A1,_Kdr*NORM.S.DIST(_sqT-_x1,1)-_Sbd*NORM.S.DIST(-_x1,1),_A2,_Kdr*NORM.S.DIST(_sqT-_x2,1)-_Sbd*NORM.S.DIST(-_x2,1),_A3,_Kdr*_h2m*NORM.S.DIST(_y1-_sqT,1)-_Sbd*_h2m1*NORM.S.DIST(_y1,1),_A4,_Kdr*_h2m*NORM.S.DIST(_y2-_sqT,1)-_Sbd*_h2m1*NORM.S.DIST(_y2,1),_do,IF(_S<=_H,0,_A1-_A2+_A3-_A4),_cf,_Sbd*NORM.S.DIST(-_x1,1)+_Kdr*NORM.S.DIST(_x1-_sqT,1),IF(_S<=_H,_cf,_do+_cf)) | F16: Price_sigm (sig -2pp)
A17: Theta (per day) | B17: =($E$17-$E$12)/dT/365 | C17: +0.357 | D17: Per 1 calendar day | E17: =LET(_S,$B$3,_sig,$B$4,_T,$B$5-dT,_r,$B$6,_K,Cap,_H,Barrier,_q,q,_b,_r-_q,_sqT,_sig*SQRT(_T),_mu,(_b-0.5*_sig^2)/_sig^2,_x1,LN(_S/_K)/_sqT+(1+_mu)*_sqT,_x2,LN(_S/_H)/_sqT+(1+_mu)*_sqT,_y1,LN(_H^2/(_S*_K))/_sqT+(1+_mu)*_sqT,_y2,LN(_H/_S)/_sqT+(1+_mu)*_sqT,_Sbd,_S*EXP(-_q*_T),_Kdr,_K*EXP(-_r*_T),_h2m1,(_H/_S)^(2*(_mu+1)),_h2m,(_H/_S)^(2*_mu),_A1,_Kdr*NORM.S.DIST(_sqT-_x1,1)-_Sbd*NORM.S.DIST(-_x1,1),_A2,_Kdr*NORM.S.DIST(_sqT-_x2,1)-_Sbd*NORM.S.DIST(-_x2,1),_A3,_Kdr*_h2m*NORM.S.DIST(_y1-_sqT,1)-_Sbd*_h2m1*NORM.S.DIST(_y1,1),_A4,_Kdr*_h2m*NORM.S.DIST(_y2-_sqT,1)-_Sbd*_h2m1*NORM.S.DIST(_y2,1),_do,IF(_S<=_H,0,_A1-_A2+_A3-_A4),_cf,_Sbd*NORM.S.DIST(-_x1,1)+_Kdr*NORM.S.DIST(_x1-_sqT,1),IF(_S<=_H,_cf,_do+_cf)) | F17: Price_Tm (T -1day)
A18: Rho (per 1% r) | B18: =($E$18-$E$19)/(2*dR)/100 | C18: N/A | D18: Bonus Greek, no specific target | E18: =LET(_S,$B$3,_sig,$B$4,_T,$B$5,_r,$B$6+dR,_K,Cap,_H,Barrier,_q,q,_b,_r-_q,_sqT,_sig*SQRT(_T),_mu,(_b-0.5*_sig^2)/_sig^2,_x1,LN(_S/_K)/_sqT+(1+_mu)*_sqT,_x2,LN(_S/_H)/_sqT+(1+_mu)*_sqT,_y1,LN(_H^2/(_S*_K))/_sqT+(1+_mu)*_sqT,_y2,LN(_H/_S)/_sqT+(1+_mu)*_sqT,_Sbd,_S*EXP(-_q*_T),_Kdr,_K*EXP(-_r*_T),_h2m1,(_H/_S)^(2*(_mu+1)),_h2m,(_H/_S)^(2*_mu),_A1,_Kdr*NORM.S.DIST(_sqT-_x1,1)-_Sbd*NORM.S.DIST(-_x1,1),_A2,_Kdr*NORM.S.DIST(_sqT-_x2,1)-_Sbd*NORM.S.DIST(-_x2,1),_A3,_Kdr*_h2m*NORM.S.DIST(_y1-_sqT,1)-_Sbd*_h2m1*NORM.S.DIST(_y1,1),_A4,_Kdr*_h2m*NORM.S.DIST(_y2-_sqT,1)-_Sbd*_h2m1*NORM.S.DIST(_y2,1),_do,IF(_S<=_H,0,_A1-_A2+_A3-_A4),_cf,_Sbd*NORM.S.DIST(-_x1,1)+_Kdr*NORM.S.DIST(_x1-_sqT,1),IF(_S<=_H,_cf,_do+_cf)) | F18: Price_rp (r +1bp)
E19: =LET(_S,$B$3,_sig,$B$4,_T,$B$5,_r,$B$6-dR,_K,Cap,_H,Barrier,_q,q,_b,_r-_q,_sqT,_sig*SQRT(_T),_mu,(_b-0.5*_sig^2)/_sig^2,_x1,LN(_S/_K)/_sqT+(1+_mu)*_sqT,_x2,LN(_S/_H)/_sqT+(1+_mu)*_sqT,_y1,LN(_H^2/(_S*_K))/_sqT+(1+_mu)*_sqT,_y2,LN(_H/_S)/_sqT+(1+_mu)*_sqT,_Sbd,_S*EXP(-_q*_T),_Kdr,_K*EXP(-_r*_T),_h2m1,(_H/_S)^(2*(_mu+1)),_h2m,(_H/_S)^(2*_mu),_A1,_Kdr*NORM.S.DIST(_sqT-_x1,1)-_Sbd*NORM.S.DIST(-_x1,1),_A2,_Kdr*NORM.S.DIST(_sqT-_x2,1)-_Sbd*NORM.S.DIST(-_x2,1),_A3,_Kdr*_h2m*NORM.S.DIST(_y1-_sqT,1)-_Sbd*_h2m1*NORM.S.DIST(_y1,1),_A4,_Kdr*_h2m*NORM.S.DIST(_y2-_sqT,1)-_Sbd*_h2m1*NORM.S.DIST(_y2,1),_do,IF(_S<=_H,0,_A1-_A2+_A3-_A4),_cf,_Sbd*NORM.S.DIST(-_x1,1)+_Kdr*NORM.S.DIST(_x1-_sqT,1),IF(_S<=_H,_cf,_do+_cf)) | F19: Price_rm (r -1bp)
A22: METHODOLOGICAL NOTE: RR closed-form delta at this reference point is approximately 0.532 (this sheet, live formula in B14) versus 0.244901 from the N=200 binomial tree (Python notebook Cell 45). The discrepancy arises because the RR formula treats the barrier as continuously monitored whereas the N=200 tree monitors at 200 discrete steps over 1.79 years. The Python notebook binomial tree is the AUTHORITATIVE engine; RR values here are provided as a cross-check only.
A24: Greeks cross-section (100 S values, RR closed-form -- live formulas)
A25: S (EUR) | B25: Price (EUR) | C25: Delta | D25: Gamma | E25: Vega (per 1%) | F25: Theta (per day)
A26: 577.5 | B26: =LET(_S,A26,_sig,$B$4,_T,$B$5,_r,$B$6,_K,Cap,_H,Barrier,_q,q,_b,_r-_q,_sqT,_sig*SQRT(_T),_mu,(_b-0.5*_sig^2)/_sig^2,_x1,LN(_S/_K)/_sqT+(1+_mu)*_sqT,_x2,LN(_S/_H)/_sqT+(1+_mu)*_sqT,_y1,LN(_H^2/(_S*_K))/_sqT+(1+_mu)*_sqT,_y2,LN(_H/_S)/_sqT+(1+_mu)*_sqT,_Sbd,_S*EXP(-_q*_T),_Kdr,_K*EXP(-_r*_T),_h2m1,(_H/_S)^(2*(_mu+1)),_h2m,(_H/_S)^(2*_mu),_A1,_Kdr*NORM.S.DIST(_sqT-_x1,1)-_Sbd*NORM.S.DIST(-_x1,1),_A2,_Kdr*NORM.S.DIST(_sqT-_x2,1)-_Sbd*NORM.S.DIST(-_x2,1),_A3,_Kdr*_h2m*NORM.S.DIST(_y1-_sqT,1)-_Sbd*_h2m1*NORM.S.DIST(_y1,1),_A4,_Kdr*_h2m*NORM.S.DIST(_y2-_sqT,1)-_Sbd*_h2m1*NORM.S.DIST(_y2,1),_do,IF(_S<=_H,0,_A1-_A2+_A3-_A4),_cf,_Sbd*NORM.S.DIST(-_x1,1)+_Kdr*NORM.S.DIST(_x1-_sqT,1),IF(_S<=_H,_cf,_do+_cf)) | C26: =LET(_S,A26,_sig,$B$4,_T,$B$5,_r,$B$6,_K,Cap,_H,Barrier,_q,q,_ds,dS,_b,_r-_q,_sqT,_sig*SQRT(_T),_mu,(_b-0.5*_sig^2)/_sig^2,_Kdr,_K*EXP(-_r*_T),_SP,_S*(1+_ds),_Sbdp,_SP*EXP(-_q*_T),_x1p,LN(_SP/_K)/_sqT+(1+_mu)*_sqT,_x2p,LN(_SP/_H)/_sqT+(1+_mu)*_sqT,_y1p,LN(_H^2/(_SP*_K))/_sqT+(1+_mu)*_sqT,_y2p,LN(_H/_SP)/_sqT+(1+_mu)*_sqT,_h2m1p,(_H/_SP)^(2*(_mu+1)),_h2mp,(_H/_SP)^(2*_mu),_A1p,_Kdr*NORM.S.DIST(_sqT-_x1p,1)-_Sbdp*NORM.S.DIST(-_x1p,1),_A2p,_Kdr*NORM.S.DIST(_sqT-_x2p,1)-_Sbdp*NORM.S.DIST(-_x2p,1),_A3p,_Kdr*_h2mp*NORM.S.DIST(_y1p-_sqT,1)-_Sbdp*_h2m1p*NORM.S.DIST(_y1p,1),_A4p,_Kdr*_h2mp*NORM.S.DIST(_y2p-_sqT,1)-_Sbdp*_h2m1p*NORM.S.DIST(_y2p,1),_cfp,_Sbdp*NORM.S.DIST(-_x1p,1)+_Kdr*NORM.S.DIST(_x1p-_sqT,1),_pp,IF(_SP<=_H,_cfp,(_A1p-_A2p+_A3p-_A4p)+_cfp),_SM,_S*(1-_ds),_Sbdm,_SM*EXP(-_q*_T),_x1m,LN(_SM/_K)/_sqT+(1+_mu)*_sqT,_x2m,LN(_SM/_H)/_sqT+(1+_mu)*_sqT,_y1m,LN(_H^2/(_SM*_K))/_sqT+(1+_mu)*_sqT,_y2m,LN(_H/_SM)/_sqT+(1+_mu)*_sqT,_h2m1m,(_H/_SM)^(2*(_mu+1)),_h2mm,(_H/_SM)^(2*_mu),_A1m,_Kdr*NORM.S.DIST(_sqT-_x1m,1)-_Sbdm*NORM.S.DIST(-_x1m,1),_A2m,_Kdr*NORM.S.DIST(_sqT-_x2m,1)-_Sbdm*NORM.S.DIST(-_x2m,1),_A3m,_Kdr*_h2mm*NORM.S.DIST(_y1m-_sqT,1)-_Sbdm*_h2m1m*NORM.S.DIST(_y1m,1),_A4m,_Kdr*_h2mm*NORM.S.DIST(_y2m-_sqT,1)-_Sbdm*_h2m1m*NORM.S.DIST(_y2m,1),_cfm,_Sbdm*NORM.S.DIST(-_x1m,1)+_Kdr*NORM.S.DIST(_x1m-_sqT,1),_pm,IF(_SM<=_H,_cfm,(_A1m-_A2m+_A3m-_A4m)+_cfm),(_pp-_pm)/(2*_ds*_S)) | D26: -0.000249 | E26: -0.6609 | F26: 0.0325
A27: 603.99 | B27: =LET(_S,A27,_sig,$B$4,_T,$B$5,_r,$B$6,_K,Cap,_H,Barrier,_q,q,_b,_r-_q,_sqT,_sig*SQRT(_T),_mu,(_b-0.5*_sig^2)/_sig^2,_x1,LN(_S/_K)/_sqT+(1+_mu)*_sqT,_x2,LN(_S/_H)/_sqT+(1+_mu)*_sqT,_y1,LN(_H^2/(_S*_K))/_sqT+(1+_mu)*_sqT,_y2,LN(_H/_S)/_sqT+(1+_mu)*_sqT,_Sbd,_S*EXP(-_q*_T),_Kdr,_K*EXP(-_r*_T),_h2m1,(_H/_S)^(2*(_mu+1)),_h2m,(_H/_S)^(2*_mu),_A1,_Kdr*NORM.S.DIST(_sqT-_x1,1)-_Sbd*NORM.S.DIST(-_x1,1),_A2,_Kdr*NORM.S.DIST(_sqT-_x2,1)-_Sbd*NORM.S.DIST(-_x2,1),_A3,_Kdr*_h2m*NORM.S.DIST(_y1-_sqT,1)-_Sbd*_h2m1*NORM.S.DIST(_y1,1),_A4,_Kdr*_h2m*NORM.S.DIST(_y2-_sqT,1)-_Sbd*_h2m1*NORM.S.DIST(_y2,1),_do,IF(_S<=_H,0,_A1-_A2+_A3-_A4),_cf,_Sbd*NORM.S.DIST(-_x1,1)+_Kdr*NORM.S.DIST(_x1-_sqT,1),IF(_S<=_H,_cf,_do+_cf)) | C27: =LET(_S,A27,_sig,$B$4,_T,$B$5,_r,$B$6,_K,Cap,_H,Barrier,_q,q,_ds,dS,_b,_r-_q,_sqT,_sig*SQRT(_T),_mu,(_b-0.5*_sig^2)/_sig^2,_Kdr,_K*EXP(-_r*_T),_SP,_S*(1+_ds),_Sbdp,_SP*EXP(-_q*_T),_x1p,LN(_SP/_K)/_sqT+(1+_mu)*_sqT,_x2p,LN(_SP/_H)/_sqT+(1+_mu)*_sqT,_y1p,LN(_H^2/(_SP*_K))/_sqT+(1+_mu)*_sqT,_y2p,LN(_H/_SP)/_sqT+(1+_mu)*_sqT,_h2m1p,(_H/_SP)^(2*(_mu+1)),_h2mp,(_H/_SP)^(2*_mu),_A1p,_Kdr*NORM.S.DIST(_sqT-_x1p,1)-_Sbdp*NORM.S.DIST(-_x1p,1),_A2p,_Kdr*NORM.S.DIST(_sqT-_x2p,1)-_Sbdp*NORM.S.DIST(-_x2p,1),_A3p,_Kdr*_h2mp*NORM.S.DIST(_y1p-_sqT,1)-_Sbdp*_h2m1p*NORM.S.DIST(_y1p,1),_A4p,_Kdr*_h2mp*NORM.S.DIST(_y2p-_sqT,1)-_Sbdp*_h2m1p*NORM.S.DIST(_y2p,1),_cfp,_Sbdp*NORM.S.DIST(-_x1p,1)+_Kdr*NORM.S.DIST(_x1p-_sqT,1),_pp,IF(_SP<=_H,_cfp,(_A1p-_A2p+_A3p-_A4p)+_cfp),_SM,_S*(1-_ds),_Sbdm,_SM*EXP(-_q*_T),_x1m,LN(_SM/_K)/_sqT+(1+_mu)*_sqT,_x2m,LN(_SM/_H)/_sqT+(1+_mu)*_sqT,_y1m,LN(_H^2/(_SM*_K))/_sqT+(1+_mu)*_sqT,_y2m,LN(_H/_SM)/_sqT+(1+_mu)*_sqT,_h2m1m,(_H/_SM)^(2*(_mu+1)),_h2mm,(_H/_SM)^(2*_mu),_A1m,_Kdr*NORM.S.DIST(_sqT-_x1m,1)-_Sbdm*NORM.S.DIST(-_x1m,1),_A2m,_Kdr*NORM.S.DIST(_sqT-_x2m,1)-_Sbdm*NORM.S.DIST(-_x2m,1),_A3m,_Kdr*_h2mm*NORM.S.DIST(_y1m-_sqT,1)-_Sbdm*_h2m1m*NORM.S.DIST(_y1m,1),_A4m,_Kdr*_h2mm*NORM.S.DIST(_y2m-_sqT,1)-_Sbdm*_h2m1m*NORM.S.DIST(_y2m,1),_cfm,_Sbdm*NORM.S.DIST(-_x1m,1)+_Kdr*NORM.S.DIST(_x1m-_sqT,1),_pm,IF(_SM<=_H,_cfm,(_A1m-_A2m+_A3m-_A4m)+_cfm),(_pp-_pm)/(2*_ds*_S)) | D27: -0.00027 | E27: -0.7859 | F27: 0.0373
A28: 630.48 | B28: =LET(_S,A28,_sig,$B$4,_T,$B$5,_r,$B$6,_K,Cap,_H,Barrier,_q,q,_b,_r-_q,_sqT,_sig*SQRT(_T),_mu,(_b-0.5*_sig^2)/_sig^2,_x1,LN(_S/_K)/_sqT+(1+_mu)*_sqT,_x2,LN(_S/_H)/_sqT+(1+_mu)*_sqT,_y1,LN(_H^2/(_S*_K))/_sqT+(1+_mu)*_sqT,_y2,LN(_H/_S)/_sqT+(1+_mu)*_sqT,_Sbd,_S*EXP(-_q*_T),_Kdr,_K*EXP(-_r*_T),_h2m1,(_H/_S)^(2*(_mu+1)),_h2m,(_H/_S)^(2*_mu),_A1,_Kdr*NORM.S.DIST(_sqT-_x1,1)-_Sbd*NORM.S.DIST(-_x1,1),_A2,_Kdr*NORM.S.DIST(_sqT-_x2,1)-_Sbd*NORM.S.DIST(-_x2,1),_A3,_Kdr*_h2m*NORM.S.DIST(_y1-_sqT,1)-_Sbd*_h2m1*NORM.S.DIST(_y1,1),_A4,_Kdr*_h2m*NORM.S.DIST(_y2-_sqT,1)-_Sbd*_h2m1*NORM.S.DIST(_y2,1),_do,IF(_S<=_H,0,_A1-_A2+_A3-_A4),_cf,_Sbd*NORM.S.DIST(-_x1,1)+_Kdr*NORM.S.DIST(_x1-_sqT,1),IF(_S<=_H,_cf,_do+_cf)) | C28: =LET(_S,A28,_sig,$B$4,_T,$B$5,_r,$B$6,_K,Cap,_H,Barrier,_q,q,_ds,dS,_b,_r-_q,_sqT,_sig*SQRT(_T),_mu,(_b-0.5*_sig^2)/_sig^2,_Kdr,_K*EXP(-_r*_T),_SP,_S*(1+_ds),_Sbdp,_SP*EXP(-_q*_T),_x1p,LN(_SP/_K)/_sqT+(1+_mu)*_sqT,_x2p,LN(_SP/_H)/_sqT+(1+_mu)*_sqT,_y1p,LN(_H^2/(_SP*_K))/_sqT+(1+_mu)*_sqT,_y2p,LN(_H/_SP)/_sqT+(1+_mu)*_sqT,_h2m1p,(_H/_SP)^(2*(_mu+1)),_h2mp,(_H/_SP)^(2*_mu),_A1p,_Kdr*NORM.S.DIST(_sqT-_x1p,1)-_Sbdp*NORM.S.DIST(-_x1p,1),_A2p,_Kdr*NORM.S.DIST(_sqT-_x2p,1)-_Sbdp*NORM.S.DIST(-_x2p,1),_A3p,_Kdr*_h2mp*NORM.S.DIST(_y1p-_sqT,1)-_Sbdp*_h2m1p*NORM.S.DIST(_y1p,1),_A4p,_Kdr*_h2mp*NORM.S.DIST(_y2p-_sqT,1)-_Sbdp*_h2m1p*NORM.S.DIST(_y2p,1),_cfp,_Sbdp*NORM.S.DIST(-_x1p,1)+_Kdr*NORM.S.DIST(_x1p-_sqT,1),_pp,IF(_SP<=_H,_cfp,(_A1p-_A2p+_A3p-_A4p)+_cfp),_SM,_S*(1-_ds),_Sbdm,_SM*EXP(-_q*_T),_x1m,LN(_SM/_K)/_sqT+(1+_mu)*_sqT,_x2m,LN(_SM/_H)/_sqT+(1+_mu)*_sqT,_y1m,LN(_H^2/(_SM*_K))/_sqT+(1+_mu)*_sqT,_y2m,LN(_H/_SM)/_sqT+(1+_mu)*_sqT,_h2m1m,(_H/_SM)^(2*(_mu+1)),_h2mm,(_H/_SM)^(2*_mu),_A1m,_Kdr*NORM.S.DIST(_sqT-_x1m,1)-_Sbdm*NORM.S.DIST(-_x1m,1),_A2m,_Kdr*NORM.S.DIST(_sqT-_x2m,1)-_Sbdm*NORM.S.DIST(-_x2m,1),_A3m,_Kdr*_h2mm*NORM.S.DIST(_y1m-_sqT,1)-_Sbdm*_h2m1m*NORM.S.DIST(_y1m,1),_A4m,_Kdr*_h2mm*NORM.S.DIST(_y2m-_sqT,1)-_Sbdm*_h2m1m*NORM.S.DIST(_y2m,1),_cfm,_Sbdm*NORM.S.DIST(-_x1m,1)+_Kdr*NORM.S.DIST(_x1m-_sqT,1),_pm,IF(_SM<=_H,_cfm,(_A1m-_A2m+_A3m-_A4m)+_cfm),(_pp-_pm)/(2*_ds*_S)) | D28: -0.000292 | E28: -0.9228 | F28: 0.0426
A29: 656.97 | B29: =LET(_S,A29,_sig,$B$4,_T,$B$5,_r,$B$6,_K,Cap,_H,Barrier,_q,q,_b,_r-_q,_sqT,_sig*SQRT(_T),_mu,(_b-0.5*_sig^2)/_sig^2,_x1,LN(_S/_K)/_sqT+(1+_mu)*_sqT,_x2,LN(_S/_H)/_sqT+(1+_mu)*_sqT,_y1,LN(_H^2/(_S*_K))/_sqT+(1+_mu)*_sqT,_y2,LN(_H/_S)/_sqT+(1+_mu)*_sqT,_Sbd,_S*EXP(-_q*_T),_Kdr,_K*EXP(-_r*_T),_h2m1,(_H/_S)^(2*(_mu+1)),_h2m,(_H/_S)^(2*_mu),_A1,_Kdr*NORM.S.DIST(_sqT-_x1,1)-_Sbd*NORM.S.DIST(-_x1,1),_A2,_Kdr*NORM.S.DIST(_sqT-_x2,1)-_Sbd*NORM.S.DIST(-_x2,1),_A3,_Kdr*_h2m*NORM.S.DIST(_y1-_sqT,1)-_Sbd*_h2m1*NORM.S.DIST(_y1,1),_A4,_Kdr*_h2m*NORM.S.DIST(_y2-_sqT,1)-_Sbd*_h2m1*NORM.S.DIST(_y2,1),_do,IF(_S<=_H,0,_A1-_A2+_A3-_A4),_cf,_Sbd*NORM.S.DIST(-_x1,1)+_Kdr*NORM.S.DIST(_x1-_sqT,1),IF(_S<=_H,_cf,_do+_cf)) | C29: =LET(_S,A29,_sig,$B$4,_T,$B$5,_r,$B$6,_K,Cap,_H,Barrier,_q,q,_ds,dS,_b,_r-_q,_sqT,_sig*SQRT(_T),_mu,(_b-0.5*_sig^2)/_sig^2,_Kdr,_K*EXP(-_r*_T),_SP,_S*(1+_ds),_Sbdp,_SP*EXP(-_q*_T),_x1p,LN(_SP/_K)/_sqT+(1+_mu)*_sqT,_x2p,LN(_SP/_H)/_sqT+(1+_mu)*_sqT,_y1p,LN(_H^2/(_SP*_K))/_sqT+(1+_mu)*_sqT,_y2p,LN(_H/_SP)/_sqT+(1+_mu)*_sqT,_h2m1p,(_H/_SP)^(2*(_mu+1)),_h2mp,(_H/_SP)^(2*_mu),_A1p,_Kdr*NORM.S.DIST(_sqT-_x1p,1)-_Sbdp*NORM.S.DIST(-_x1p,1),_A2p,_Kdr*NORM.S.DIST(_sqT-_x2p,1)-_Sbdp*NORM.S.DIST(-_x2p,1),_A3p,_Kdr*_h2mp*NORM.S.DIST(_y1p-_sqT,1)-_Sbdp*_h2m1p*NORM.S.DIST(_y1p,1),_A4p,_Kdr*_h2mp*NORM.S.DIST(_y2p-_sqT,1)-_Sbdp*_h2m1p*NORM.S.DIST(_y2p,1),_cfp,_Sbdp*NORM.S.DIST(-_x1p,1)+_Kdr*NORM.S.DIST(_x1p-_sqT,1),_pp,IF(_SP<=_H,_cfp,(_A1p-_A2p+_A3p-_A4p)+_cfp),_SM,_S*(1-_ds),_Sbdm,_SM*EXP(-_q*_T),_x1m,LN(_SM/_K)/_sqT+(1+_mu)*_sqT,_x2m,LN(_SM/_H)/_sqT+(1+_mu)*_sqT,_y1m,LN(_H^2/(_SM*_K))/_sqT+(1+_mu)*_sqT,_y2m,LN(_H/_SM)/_sqT+(1+_mu)*_sqT,_h2m1m,(_H/_SM)^(2*(_mu+1)),_h2mm,(_H/_SM)^(2*_mu),_A1m,_Kdr*NORM.S.DIST(_sqT-_x1m,1)-_Sbdm*NORM.S.DIST(-_x1m,1),_A2m,_Kdr*NORM.S.DIST(_sqT-_x2m,1)-_Sbdm*NORM.S.DIST(-_x2m,1),_A3m,_Kdr*_h2mm*NORM.S.DIST(_y1m-_sqT,1)-_Sbdm*_h2m1m*NORM.S.DIST(_y1m,1),_A4m,_Kdr*_h2mm*NORM.S.DIST(_y2m-_sqT,1)-_Sbdm*_h2m1m*NORM.S.DIST(_y2m,1),_cfm,_Sbdm*NORM.S.DIST(-_x1m,1)+_Kdr*NORM.S.DIST(_x1m-_sqT,1),_pm,IF(_SM<=_H,_cfm,(_A1m-_A2m+_A3m-_A4m)+_cfm),(_pp-_pm)/(2*_ds*_S)) | D29: -0.000312 | E29: -1.0712 | F29: 0.0482
A30: 683.46 | B30: =LET(_S,A30,_sig,$B$4,_T,$B$5,_r,$B$6,_K,Cap,_H,Barrier,_q,q,_b,_r-_q,_sqT,_sig*SQRT(_T),_mu,(_b-0.5*_sig^2)/_sig^2,_x1,LN(_S/_K)/_sqT+(1+_mu)*_sqT,_x2,LN(_S/_H)/_sqT+(1+_mu)*_sqT,_y1,LN(_H^2/(_S*_K))/_sqT+(1+_mu)*_sqT,_y2,LN(_H/_S)/_sqT+(1+_mu)*_sqT,_Sbd,_S*EXP(-_q*_T),_Kdr,_K*EXP(-_r*_T),_h2m1,(_H/_S)^(2*(_mu+1)),_h2m,(_H/_S)^(2*_mu),_A1,_Kdr*NORM.S.DIST(_sqT-_x1,1)-_Sbd*NORM.S.DIST(-_x1,1),_A2,_Kdr*NORM.S.DIST(_sqT-_x2,1)-_Sbd*NORM.S.DIST(-_x2,1),_A3,_Kdr*_h2m*NORM.S.DIST(_y1-_sqT,1)-_Sbd*_h2m1*NORM.S.DIST(_y1,1),_A4,_Kdr*_h2m*NORM.S.DIST(_y2-_sqT,1)-_Sbd*_h2m1*NORM.S.DIST(_y2,1),_do,IF(_S<=_H,0,_A1-_A2+_A3-_A4),_cf,_Sbd*NORM.S.DIST(-_x1,1)+_Kdr*NORM.S.DIST(_x1-_sqT,1),IF(_S<=_H,_cf,_do+_cf)) | C30: =LET(_S,A30,_sig,$B$4,_T,$B$5,_r,$B$6,_K,Cap,_H,Barrier,_q,q,_ds,dS,_b,_r-_q,_sqT,_sig*SQRT(_T),_mu,(_b-0.5*_sig^2)/_sig^2,_Kdr,_K*EXP(-_r*_T),_SP,_S*(1+_ds),_Sbdp,_SP*EXP(-_q*_T),_x1p,LN(_SP/_K)/_sqT+(1+_mu)*_sqT,_x2p,LN(_SP/_H)/_sqT+(1+_mu)*_sqT,_y1p,LN(_H^2/(_SP*_K))/_sqT+(1+_mu)*_sqT,_y2p,LN(_H/_SP)/_sqT+(1+_mu)*_sqT,_h2m1p,(_H/_SP)^(2*(_mu+1)),_h2mp,(_H/_SP)^(2*_mu),_A1p,_Kdr*NORM.S.DIST(_sqT-_x1p,1)-_Sbdp*NORM.S.DIST(-_x1p,1),_A2p,_Kdr*NORM.S.DIST(_sqT-_x2p,1)-_Sbdp*NORM.S.DIST(-_x2p,1),_A3p,_Kdr*_h2mp*NORM.S.DIST(_y1p-_sqT,1)-_Sbdp*_h2m1p*NORM.S.DIST(_y1p,1),_A4p,_Kdr*_h2mp*NORM.S.DIST(_y2p-_sqT,1)-_Sbdp*_h2m1p*NORM.S.DIST(_y2p,1),_cfp,_Sbdp*NORM.S.DIST(-_x1p,1)+_Kdr*NORM.S.DIST(_x1p-_sqT,1),_pp,IF(_SP<=_H,_cfp,(_A1p-_A2p+_A3p-_A4p)+_cfp),_SM,_S*(1-_ds),_Sbdm,_SM*EXP(-_q*_T),_x1m,LN(_SM/_K)/_sqT+(1+_mu)*_sqT,_x2m,LN(_SM/_H)/_sqT+(1+_mu)*_sqT,_y1m,LN(_H^2/(_SM*_K))/_sqT+(1+_mu)*_sqT,_y2m,LN(_H/_SM)/_sqT+(1+_mu)*_sqT,_h2m1m,(_H/_SM)^(2*(_mu+1)),_h2mm,(_H/_SM)^(2*_mu),_A1m,_Kdr*NORM.S.DIST(_sqT-_x1m,1)-_Sbdm*NORM.S.DIST(-_x1m,1),_A2m,_Kdr*NORM.S.DIST(_sqT-_x2m,1)-_Sbdm*NORM.S.DIST(-_x2m,1),_A3m,_Kdr*_h2mm*NORM.S.DIST(_y1m-_sqT,1)-_Sbdm*_h2m1m*NORM.S.DIST(_y1m,1),_A4m,_Kdr*_h2mm*NORM.S.DIST(_y2m-_sqT,1)-_Sbdm*_h2m1m*NORM.S.DIST(_y2m,1),_cfm,_Sbdm*NORM.S.DIST(-_x1m,1)+_Kdr*NORM.S.DIST(_x1m-_sqT,1),_pm,IF(_SM<=_H,_cfm,(_A1m-_A2m+_A3m-_A4m)+_cfm),(_pp-_pm)/(2*_ds*_S)) | D30: -0.000331 | E30: -1.2307 | F30: 0.0543
A31: 709.95 | B31: =LET(_S,A31,_sig,$B$4,_T,$B$5,_r,$B$6,_K,Cap,_H,Barrier,_q,q,_b,_r-_q,_sqT,_sig*SQRT(_T),_mu,(_b-0.5*_sig^2)/_sig^2,_x1,LN(_S/_K)/_sqT+(1+_mu)*_sqT,_x2,LN(_S/_H)/_sqT+(1+_mu)*_sqT,_y1,LN(_H^2/(_S*_K))/_sqT+(1+_mu)*_sqT,_y2,LN(_H/_S)/_sqT+(1+_mu)*_sqT,_Sbd,_S*EXP(-_q*_T),_Kdr,_K*EXP(-_r*_T),_h2m1,(_H/_S)^(2*(_mu+1)),_h2m,(_H/_S)^(2*_mu),_A1,_Kdr*NORM.S.DIST(_sqT-_x1,1)-_Sbd*NORM.S.DIST(-_x1,1),_A2,_Kdr*NORM.S.DIST(_sqT-_x2,1)-_Sbd*NORM.S.DIST(-_x2,1),_A3,_Kdr*_h2m*NORM.S.DIST(_y1-_sqT,1)-_Sbd*_h2m1*NORM.S.DIST(_y1,1),_A4,_Kdr*_h2m*NORM.S.DIST(_y2-_sqT,1)-_Sbd*_h2m1*NORM.S.DIST(_y2,1),_do,IF(_S<=_H,0,_A1-_A2+_A3-_A4),_cf,_Sbd*NORM.S.DIST(-_x1,1)+_Kdr*NORM.S.DIST(_x1-_sqT,1),IF(_S<=_H,_cf,_do+_cf)) | C31: =LET(_S,A31,_sig,$B$4,_T,$B$5,_r,$B$6,_K,Cap,_H,Barrier,_q,q,_ds,dS,_b,_r-_q,_sqT,_sig*SQRT(_T),_mu,(_b-0.5*_sig^2)/_sig^2,_Kdr,_K*EXP(-_r*_T),_SP,_S*(1+_ds),_Sbdp,_SP*EXP(-_q*_T),_x1p,LN(_SP/_K)/_sqT+(1+_mu)*_sqT,_x2p,LN(_SP/_H)/_sqT+(1+_mu)*_sqT,_y1p,LN(_H^2/(_SP*_K))/_sqT+(1+_mu)*_sqT,_y2p,LN(_H/_SP)/_sqT+(1+_mu)*_sqT,_h2m1p,(_H/_SP)^(2*(_mu+1)),_h2mp,(_H/_SP)^(2*_mu),_A1p,_Kdr*NORM.S.DIST(_sqT-_x1p,1)-_Sbdp*NORM.S.DIST(-_x1p,1),_A2p,_Kdr*NORM.S.DIST(_sqT-_x2p,1)-_Sbdp*NORM.S.DIST(-_x2p,1),_A3p,_Kdr*_h2mp*NORM.S.DIST(_y1p-_sqT,1)-_Sbdp*_h2m1p*NORM.S.DIST(_y1p,1),_A4p,_Kdr*_h2mp*NORM.S.DIST(_y2p-_sqT,1)-_Sbdp*_h2m1p*NORM.S.DIST(_y2p,1),_cfp,_Sbdp*NORM.S.DIST(-_x1p,1)+_Kdr*NORM.S.DIST(_x1p-_sqT,1),_pp,IF(_SP<=_H,_cfp,(_A1p-_A2p+_A3p-_A4p)+_cfp),_SM,_S*(1-_ds),_Sbdm,_SM*EXP(-_q*_T),_x1m,LN(_SM/_K)/_sqT+(1+_mu)*_sqT,_x2m,LN(_SM/_H)/_sqT+(1+_mu)*_sqT,_y1m,LN(_H^2/(_SM*_K))/_sqT+(1+_mu)*_sqT,_y2m,LN(_H/_SM)/_sqT+(1+_mu)*_sqT,_h2m1m,(_H/_SM)^(2*(_mu+1)),_h2mm,(_H/_SM)^(2*_mu),_A1m,_Kdr*NORM.S.DIST(_sqT-_x1m,1)-_Sbdm*NORM.S.DIST(-_x1m,1),_A2m,_Kdr*NORM.S.DIST(_sqT-_x2m,1)-_Sbdm*NORM.S.DIST(-_x2m,1),_A3m,_Kdr*_h2mm*NORM.S.DIST(_y1m-_sqT,1)-_Sbdm*_h2m1m*NORM.S.DIST(_y1m,1),_A4m,_Kdr*_h2mm*NORM.S.DIST(_y2m-_sqT,1)-_Sbdm*_h2m1m*NORM.S.DIST(_y2m,1),_cfm,_Sbdm*NORM.S.DIST(-_x1m,1)+_Kdr*NORM.S.DIST(_x1m-_sqT,1),_pm,IF(_SM<=_H,_cfm,(_A1m-_A2m+_A3m-_A4m)+_cfm),(_pp-_pm)/(2*_ds*_S)) | D31: -0.000349 | E31: -1.4007 | F31: 0.0608
A32: 736.44 | B32: =LET(_S,A32,_sig,$B$4,_T,$B$5,_r,$B$6,_K,Cap,_H,Barrier,_q,q,_b,_r-_q,_sqT,_sig*SQRT(_T),_mu,(_b-0.5*_sig^2)/_sig^2,_x1,LN(_S/_K)/_sqT+(1+_mu)*_sqT,_x2,LN(_S/_H)/_sqT+(1+_mu)*_sqT,_y1,LN(_H^2/(_S*_K))/_sqT+(1+_mu)*_sqT,_y2,LN(_H/_S)/_sqT+(1+_mu)*_sqT,_Sbd,_S*EXP(-_q*_T),_Kdr,_K*EXP(-_r*_T),_h2m1,(_H/_S)^(2*(_mu+1)),_h2m,(_H/_S)^(2*_mu),_A1,_Kdr*NORM.S.DIST(_sqT-_x1,1)-_Sbd*NORM.S.DIST(-_x1,1),_A2,_Kdr*NORM.S.DIST(_sqT-_x2,1)-_Sbd*NORM.S.DIST(-_x2,1),_A3,_Kdr*_h2m*NORM.S.DIST(_y1-_sqT,1)-_Sbd*_h2m1*NORM.S.DIST(_y1,1),_A4,_Kdr*_h2m*NORM.S.DIST(_y2-_sqT,1)-_Sbd*_h2m1*NORM.S.DIST(_y2,1),_do,IF(_S<=_H,0,_A1-_A2+_A3-_A4),_cf,_Sbd*NORM.S.DIST(-_x1,1)+_Kdr*NORM.S.DIST(_x1-_sqT,1),IF(_S<=_H,_cf,_do+_cf)) | C32: =LET(_S,A32,_sig,$B$4,_T,$B$5,_r,$B$6,_K,Cap,_H,Barrier,_q,q,_ds,dS,_b,_r-_q,_sqT,_sig*SQRT(_T),_mu,(_b-0.5*_sig^2)/_sig^2,_Kdr,_K*EXP(-_r*_T),_SP,_S*(1+_ds),_Sbdp,_SP*EXP(-_q*_T),_x1p,LN(_SP/_K)/_sqT+(1+_mu)*_sqT,_x2p,LN(_SP/_H)/_sqT+(1+_mu)*_sqT,_y1p,LN(_H^2/(_SP*_K))/_sqT+(1+_mu)*_sqT,_y2p,LN(_H/_SP)/_sqT+(1+_mu)*_sqT,_h2m1p,(_H/_SP)^(2*(_mu+1)),_h2mp,(_H/_SP)^(2*_mu),_A1p,_Kdr*NORM.S.DIST(_sqT-_x1p,1)-_Sbdp*NORM.S.DIST(-_x1p,1),_A2p,_Kdr*NORM.S.DIST(_sqT-_x2p,1)-_Sbdp*NORM.S.DIST(-_x2p,1),_A3p,_Kdr*_h2mp*NORM.S.DIST(_y1p-_sqT,1)-_Sbdp*_h2m1p*NORM.S.DIST(_y1p,1),_A4p,_Kdr*_h2mp*NORM.S.DIST(_y2p-_sqT,1)-_Sbdp*_h2m1p*NORM.S.DIST(_y2p,1),_cfp,_Sbdp*NORM.S.DIST(-_x1p,1)+_Kdr*NORM.S.DIST(_x1p-_sqT,1),_pp,IF(_SP<=_H,_cfp,(_A1p-_A2p+_A3p-_A4p)+_cfp),_SM,_S*(1-_ds),_Sbdm,_SM*EXP(-_q*_T),_x1m,LN(_SM/_K)/_sqT+(1+_mu)*_sqT,_x2m,LN(_SM/_H)/_sqT+(1+_mu)*_sqT,_y1m,LN(_H^2/(_SM*_K))/_sqT+(1+_mu)*_sqT,_y2m,LN(_H/_SM)/_sqT+(1+_mu)*_sqT,_h2m1m,(_H/_SM)^(2*(_mu+1)),_h2mm,(_H/_SM)^(2*_mu),_A1m,_Kdr*NORM.S.DIST(_sqT-_x1m,1)-_Sbdm*NORM.S.DIST(-_x1m,1),_A2m,_Kdr*NORM.S.DIST(_sqT-_x2m,1)-_Sbdm*NORM.S.DIST(-_x2m,1),_A3m,_Kdr*_h2mm*NORM.S.DIST(_y1m-_sqT,1)-_Sbdm*_h2m1m*NORM.S.DIST(_y1m,1),_A4m,_Kdr*_h2mm*NORM.S.DIST(_y2m-_sqT,1)-_Sbdm*_h2m1m*NORM.S.DIST(_y2m,1),_cfm,_Sbdm*NORM.S.DIST(-_x1m,1)+_Kdr*NORM.S.DIST(_x1m-_sqT,1),_pm,IF(_SM<=_H,_cfm,(_A1m-_A2m+_A3m-_A4m)+_cfm),(_pp-_pm)/(2*_ds*_S)) | D32: -0.000366 | E32: -1.5806 | F32: 0.0676
A33: 762.93 | B33: =LET(_S,A33,_sig,$B$4,_T,$B$5,_r,$B$6,_K,Cap,_H,Barrier,_q,q,_b,_r-_q,_sqT,_sig*SQRT(_T),_mu,(_b-0.5*_sig^2)/_sig^2,_x1,LN(_S/_K)/_sqT+(1+_mu)*_sqT,_x2,LN(_S/_H)/_sqT+(1+_mu)*_sqT,_y1,LN(_H^2/(_S*_K))/_sqT+(1+_mu)*_sqT,_y2,LN(_H/_S)/_sqT+(1+_mu)*_sqT,_Sbd,_S*EXP(-_q*_T),_Kdr,_K*EXP(-_r*_T),_h2m1,(_H/_S)^(2*(_mu+1)),_h2m,(_H/_S)^(2*_mu),_A1,_Kdr*NORM.S.DIST(_sqT-_x1,1)-_Sbd*NORM.S.DIST(-_x1,1),_A2,_Kdr*NORM.S.DIST(_sqT-_x2,1)-_Sbd*NORM.S.DIST(-_x2,1),_A3,_Kdr*_h2m*NORM.S.DIST(_y1-_sqT,1)-_Sbd*_h2m1*NORM.S.DIST(_y1,1),_A4,_Kdr*_h2m*NORM.S.DIST(_y2-_sqT,1)-_Sbd*_h2m1*NORM.S.DIST(_y2,1),_do,IF(_S<=_H,0,_A1-_A2+_A3-_A4),_cf,_Sbd*NORM.S.DIST(-_x1,1)+_Kdr*NORM.S.DIST(_x1-_sqT,1),IF(_S<=_H,_cf,_do+_cf)) | C33: =LET(_S,A33,_sig,$B$4,_T,$B$5,_r,$B$6,_K,Cap,_H,Barrier,_q,q,_ds,dS,_b,_r-_q,_sqT,_sig*SQRT(_T),_mu,(_b-0.5*_sig^2)/_sig^2,_Kdr,_K*EXP(-_r*_T),_SP,_S*(1+_ds),_Sbdp,_SP*EXP(-_q*_T),_x1p,LN(_SP/_K)/_sqT+(1+_mu)*_sqT,_x2p,LN(_SP/_H)/_sqT+(1+_mu)*_sqT,_y1p,LN(_H^2/(_SP*_K))/_sqT+(1+_mu)*_sqT,_y2p,LN(_H/_SP)/_sqT+(1+_mu)*_sqT,_h2m1p,(_H/_SP)^(2*(_mu+1)),_h2mp,(_H/_SP)^(2*_mu),_A1p,_Kdr*NORM.S.DIST(_sqT-_x1p,1)-_Sbdp*NORM.S.DIST(-_x1p,1),_A2p,_Kdr*NORM.S.DIST(_sqT-_x2p,1)-_Sbdp*NORM.S.DIST(-_x2p,1),_A3p,_Kdr*_h2mp*NORM.S.DIST(_y1p-_sqT,1)-_Sbdp*_h2m1p*NORM.S.DIST(_y1p,1),_A4p,_Kdr*_h2mp*NORM.S.DIST(_y2p-_sqT,1)-_Sbdp*_h2m1p*NORM.S.DIST(_y2p,1),_cfp,_Sbdp*NORM.S.DIST(-_x1p,1)+_Kdr*NORM.S.DIST(_x1p-_sqT,1),_pp,IF(_SP<=_H,_cfp,(_A1p-_A2p+_A3p-_A4p)+_cfp),_SM,_S*(1-_ds),_Sbdm,_SM*EXP(-_q*_T),_x1m,LN(_SM/_K)/_sqT+(1+_mu)*_sqT,_x2m,LN(_SM/_H)/_sqT+(1+_mu)*_sqT,_y1m,LN(_H^2/(_SM*_K))/_sqT+(1+_mu)*_sqT,_y2m,LN(_H/_SM)/_sqT+(1+_mu)*_sqT,_h2m1m,(_H/_SM)^(2*(_mu+1)),_h2mm,(_H/_SM)^(2*_mu),_A1m,_Kdr*NORM.S.DIST(_sqT-_x1m,1)-_Sbdm*NORM.S.DIST(-_x1m,1),_A2m,_Kdr*NORM.S.DIST(_sqT-_x2m,1)-_Sbdm*NORM.S.DIST(-_x2m,1),_A3m,_Kdr*_h2mm*NORM.S.DIST(_y1m-_sqT,1)-_Sbdm*_h2m1m*NORM.S.DIST(_y1m,1),_A4m,_Kdr*_h2mm*NORM.S.DIST(_y2m-_sqT,1)-_Sbdm*_h2m1m*NORM.S.DIST(_y2m,1),_cfm,_Sbdm*NORM.S.DIST(-_x1m,1)+_Kdr*NORM.S.DIST(_x1m-_sqT,1),_pm,IF(_SM<=_H,_cfm,(_A1m-_A2m+_A3m-_A4m)+_cfm),(_pp-_pm)/(2*_ds*_S)) | D33: -0.000382 | E33: -1.7698 | F33: 0.0747
A34: 789.42 | B34: =LET(_S,A34,_sig,$B$4,_T,$B$5,_r,$B$6,_K,Cap,_H,Barrier,_q,q,_b,_r-_q,_sqT,_sig*SQRT(_T),_mu,(_b-0.5*_sig^2)/_sig^2,_x1,LN(_S/_K)/_sqT+(1+_mu)*_sqT,_x2,LN(_S/_H)/_sqT+(1+_mu)*_sqT,_y1,LN(_H^2/(_S*_K))/_sqT+(1+_mu)*_sqT,_y2,LN(_H/_S)/_sqT+(1+_mu)*_sqT,_Sbd,_S*EXP(-_q*_T),_Kdr,_K*EXP(-_r*_T),_h2m1,(_H/_S)^(2*(_mu+1)),_h2m,(_H/_S)^(2*_mu),_A1,_Kdr*NORM.S.DIST(_sqT-_x1,1)-_Sbd*NORM.S.DIST(-_x1,1),_A2,_Kdr*NORM.S.DIST(_sqT-_x2,1)-_Sbd*NORM.S.DIST(-_x2,1),_A3,_Kdr*_h2m*NORM.S.DIST(_y1-_sqT,1)-_Sbd*_h2m1*NORM.S.DIST(_y1,1),_A4,_Kdr*_h2m*NORM.S.DIST(_y2-_sqT,1)-_Sbd*_h2m1*NORM.S.DIST(_y2,1),_do,IF(_S<=_H,0,_A1-_A2+_A3-_A4),_cf,_Sbd*NORM.S.DIST(-_x1,1)+_Kdr*NORM.S.DIST(_x1-_sqT,1),IF(_S<=_H,_cf,_do+_cf)) | C34: =LET(_S,A34,_sig,$B$4,_T,$B$5,_r,$B$6,_K,Cap,_H,Barrier,_q,q,_ds,dS,_b,_r-_q,_sqT,_sig*SQRT(_T),_mu,(_b-0.5*_sig^2)/_sig^2,_Kdr,_K*EXP(-_r*_T),_SP,_S*(1+_ds),_Sbdp,_SP*EXP(-_q*_T),_x1p,LN(_SP/_K)/_sqT+(1+_mu)*_sqT,_x2p,LN(_SP/_H)/_sqT+(1+_mu)*_sqT,_y1p,LN(_H^2/(_SP*_K))/_sqT+(1+_mu)*_sqT,_y2p,LN(_H/_SP)/_sqT+(1+_mu)*_sqT,_h2m1p,(_H/_SP)^(2*(_mu+1)),_h2mp,(_H/_SP)^(2*_mu),_A1p,_Kdr*NORM.S.DIST(_sqT-_x1p,1)-_Sbdp*NORM.S.DIST(-_x1p,1),_A2p,_Kdr*NORM.S.DIST(_sqT-_x2p,1)-_Sbdp*NORM.S.DIST(-_x2p,1),_A3p,_Kdr*_h2mp*NORM.S.DIST(_y1p-_sqT,1)-_Sbdp*_h2m1p*NORM.S.DIST(_y1p,1),_A4p,_Kdr*_h2mp*NORM.S.DIST(_y2p-_sqT,1)-_Sbdp*_h2m1p*NORM.S.DIST(_y2p,1),_cfp,_Sbdp*NORM.S.DIST(-_x1p,1)+_Kdr*NORM.S.DIST(_x1p-_sqT,1),_pp,IF(_SP<=_H,_cfp,(_A1p-_A2p+_A3p-_A4p)+_cfp),_SM,_S*(1-_ds),_Sbdm,_SM*EXP(-_q*_T),_x1m,LN(_SM/_K)/_sqT+(1+_mu)*_sqT,_x2m,LN(_SM/_H)/_sqT+(1+_mu)*_sqT,_y1m,LN(_H^2/(_SM*_K))/_sqT+(1+_mu)*_sqT,_y2m,LN(_H/_SM)/_sqT+(1+_mu)*_sqT,_h2m1m,(_H/_SM)^(2*(_mu+1)),_h2mm,(_H/_SM)^(2*_mu),_A1m,_Kdr*NORM.S.DIST(_sqT-_x1m,1)-_Sbdm*NORM.S.DIST(-_x1m,1),_A2m,_Kdr*NORM.S.DIST(_sqT-_x2m,1)-_Sbdm*NORM.S.DIST(-_x2m,1),_A3m,_Kdr*_h2mm*NORM.S.DIST(_y1m-_sqT,1)-_Sbdm*_h2m1m*NORM.S.DIST(_y1m,1),_A4m,_Kdr*_h2mm*NORM.S.DIST(_y2m-_sqT,1)-_Sbdm*_h2m1m*NORM.S.DIST(_y2m,1),_cfm,_Sbdm*NORM.S.DIST(-_x1m,1)+_Kdr*NORM.S.DIST(_x1m-_sqT,1),_pm,IF(_SM<=_H,_cfm,(_A1m-_A2m+_A3m-_A4m)+_cfm),(_pp-_pm)/(2*_ds*_S)) | D34: -0.000397 | E34: -1.9674 | F34: 0.0821
A35: 815.91 | B35: =LET(_S,A35,_sig,$B$4,_T,$B$5,_r,$B$6,_K,Cap,_H,Barrier,_q,q,_b,_r-_q,_sqT,_sig*SQRT(_T),_mu,(_b-0.5*_sig^2)/_sig^2,_x1,LN(_S/_K)/_sqT+(1+_mu)*_sqT,_x2,LN(_S/_H)/_sqT+(1+_mu)*_sqT,_y1,LN(_H^2/(_S*_K))/_sqT+(1+_mu)*_sqT,_y2,LN(_H/_S)/_sqT+(1+_mu)*_sqT,_Sbd,_S*EXP(-_q*_T),_Kdr,_K*EXP(-_r*_T),_h2m1,(_H/_S)^(2*(_mu+1)),_h2m,(_H/_S)^(2*_mu),_A1,_Kdr*NORM.S.DIST(_sqT-_x1,1)-_Sbd*NORM.S.DIST(-_x1,1),_A2,_Kdr*NORM.S.DIST(_sqT-_x2,1)-_Sbd*NORM.S.DIST(-_x2,1),_A3,_Kdr*_h2m*NORM.S.DIST(_y1-_sqT,1)-_Sbd*_h2m1*NORM.S.DIST(_y1,1),_A4,_Kdr*_h2m*NORM.S.DIST(_y2-_sqT,1)-_Sbd*_h2m1*NORM.S.DIST(_y2,1),_do,IF(_S<=_H,0,_A1-_A2+_A3-_A4),_cf,_Sbd*NORM.S.DIST(-_x1,1)+_Kdr*NORM.S.DIST(_x1-_sqT,1),IF(_S<=_H,_cf,_do+_cf)) | C35: =LET(_S,A35,_sig,$B$4,_T,$B$5,_r,$B$6,_K,Cap,_H,Barrier,_q,q,_ds,dS,_b,_r-_q,_sqT,_sig*SQRT(_T),_mu,(_b-0.5*_sig^2)/_sig^2,_Kdr,_K*EXP(-_r*_T),_SP,_S*(1+_ds),_Sbdp,_SP*EXP(-_q*_T),_x1p,LN(_SP/_K)/_sqT+(1+_mu)*_sqT,_x2p,LN(_SP/_H)/_sqT+(1+_mu)*_sqT,_y1p,LN(_H^2/(_SP*_K))/_sqT+(1+_mu)*_sqT,_y2p,LN(_H/_SP)/_sqT+(1+_mu)*_sqT,_h2m1p,(_H/_SP)^(2*(_mu+1)),_h2mp,(_H/_SP)^(2*_mu),_A1p,_Kdr*NORM.S.DIST(_sqT-_x1p,1)-_Sbdp*NORM.S.DIST(-_x1p,1),_A2p,_Kdr*NORM.S.DIST(_sqT-_x2p,1)-_Sbdp*NORM.S.DIST(-_x2p,1),_A3p,_Kdr*_h2mp*NORM.S.DIST(_y1p-_sqT,1)-_Sbdp*_h2m1p*NORM.S.DIST(_y1p,1),_A4p,_Kdr*_h2mp*NORM.S.DIST(_y2p-_sqT,1)-_Sbdp*_h2m1p*NORM.S.DIST(_y2p,1),_cfp,_Sbdp*NORM.S.DIST(-_x1p,1)+_Kdr*NORM.S.DIST(_x1p-_sqT,1),_pp,IF(_SP<=_H,_cfp,(_A1p-_A2p+_A3p-_A4p)+_cfp),_SM,_S*(1-_ds),_Sbdm,_SM*EXP(-_q*_T),_x1m,LN(_SM/_K)/_sqT+(1+_mu)*_sqT,_x2m,LN(_SM/_H)/_sqT+(1+_mu)*_sqT,_y1m,LN(_H^2/(_SM*_K))/_sqT+(1+_mu)*_sqT,_y2m,LN(_H/_SM)/_sqT+(1+_mu)*_sqT,_h2m1m,(_H/_SM)^(2*(_mu+1)),_h2mm,(_H/_SM)^(2*_mu),_A1m,_Kdr*NORM.S.DIST(_sqT-_x1m,1)-_Sbdm*NORM.S.DIST(-_x1m,1),_A2m,_Kdr*NORM.S.DIST(_sqT-_x2m,1)-_Sbdm*NORM.S.DIST(-_x2m,1),_A3m,_Kdr*_h2mm*NORM.S.DIST(_y1m-_sqT,1)-_Sbdm*_h2m1m*NORM.S.DIST(_y1m,1),_A4m,_Kdr*_h2mm*NORM.S.DIST(_y2m-_sqT,1)-_Sbdm*_h2m1m*NORM.S.DIST(_y2m,1),_cfm,_Sbdm*NORM.S.DIST(-_x1m,1)+_Kdr*NORM.S.DIST(_x1m-_sqT,1),_pm,IF(_SM<=_H,_cfm,(_A1m-_A2m+_A3m-_A4m)+_cfm),(_pp-_pm)/(2*_ds*_S)) | D35: -0.00041 | E35: -2.1726 | F35: 0.0898
A36: 842.4 | B36: =LET(_S,A36,_sig,$B$4,_T,$B$5,_r,$B$6,_K,Cap,_H,Barrier,_q,q,_b,_r-_q,_sqT,_sig*SQRT(_T),_mu,(_b-0.5*_sig^2)/_sig^2,_x1,LN(_S/_K)/_sqT+(1+_mu)*_sqT,_x2,LN(_S/_H)/_sqT+(1+_mu)*_sqT,_y1,LN(_H^2/(_S*_K))/_sqT+(1+_mu)*_sqT,_y2,LN(_H/_S)/_sqT+(1+_mu)*_sqT,_Sbd,_S*EXP(-_q*_T),_Kdr,_K*EXP(-_r*_T),_h2m1,(_H/_S)^(2*(_mu+1)),_h2m,(_H/_S)^(2*_mu),_A1,_Kdr*NORM.S.DIST(_sqT-_x1,1)-_Sbd*NORM.S.DIST(-_x1,1),_A2,_Kdr*NORM.S.DIST(_sqT-_x2,1)-_Sbd*NORM.S.DIST(-_x2,1),_A3,_Kdr*_h2m*NORM.S.DIST(_y1-_sqT,1)-_Sbd*_h2m1*NORM.S.DIST(_y1,1),_A4,_Kdr*_h2m*NORM.S.DIST(_y2-_sqT,1)-_Sbd*_h2m1*NORM.S.DIST(_y2,1),_do,IF(_S<=_H,0,_A1-_A2+_A3-_A4),_cf,_Sbd*NORM.S.DIST(-_x1,1)+_Kdr*NORM.S.DIST(_x1-_sqT,1),IF(_S<=_H,_cf,_do+_cf)) | C36: =LET(_S,A36,_sig,$B$4,_T,$B$5,_r,$B$6,_K,Cap,_H,Barrier,_q,q,_ds,dS,_b,_r-_q,_sqT,_sig*SQRT(_T),_mu,(_b-0.5*_sig^2)/_sig^2,_Kdr,_K*EXP(-_r*_T),_SP,_S*(1+_ds),_Sbdp,_SP*EXP(-_q*_T),_x1p,LN(_SP/_K)/_sqT+(1+_mu)*_sqT,_x2p,LN(_SP/_H)/_sqT+(1+_mu)*_sqT,_y1p,LN(_H^2/(_SP*_K))/_sqT+(1+_mu)*_sqT,_y2p,LN(_H/_SP)/_sqT+(1+_mu)*_sqT,_h2m1p,(_H/_SP)^(2*(_mu+1)),_h2mp,(_H/_SP)^(2*_mu),_A1p,_Kdr*NORM.S.DIST(_sqT-_x1p,1)-_Sbdp*NORM.S.DIST(-_x1p,1),_A2p,_Kdr*NORM.S.DIST(_sqT-_x2p,1)-_Sbdp*NORM.S.DIST(-_x2p,1),_A3p,_Kdr*_h2mp*NORM.S.DIST(_y1p-_sqT,1)-_Sbdp*_h2m1p*NORM.S.DIST(_y1p,1),_A4p,_Kdr*_h2mp*NORM.S.DIST(_y2p-_sqT,1)-_Sbdp*_h2m1p*NORM.S.DIST(_y2p,1),_cfp,_Sbdp*NORM.S.DIST(-_x1p,1)+_Kdr*NORM.S.DIST(_x1p-_sqT,1),_pp,IF(_SP<=_H,_cfp,(_A1p-_A2p+_A3p-_A4p)+_cfp),_SM,_S*(1-_ds),_Sbdm,_SM*EXP(-_q*_T),_x1m,LN(_SM/_K)/_sqT+(1+_mu)*_sqT,_x2m,LN(_SM/_H)/_sqT+(1+_mu)*_sqT,_y1m,LN(_H^2/(_SM*_K))/_sqT+(1+_mu)*_sqT,_y2m,LN(_H/_SM)/_sqT+(1+_mu)*_sqT,_h2m1m,(_H/_SM)^(2*(_mu+1)),_h2mm,(_H/_SM)^(2*_mu),_A1m,_Kdr*NORM.S.DIST(_sqT-_x1m,1)-_Sbdm*NORM.S.DIST(-_x1m,1),_A2m,_Kdr*NORM.S.DIST(_sqT-_x2m,1)-_Sbdm*NORM.S.DIST(-_x2m,1),_A3m,_Kdr*_h2mm*NORM.S.DIST(_y1m-_sqT,1)-_Sbdm*_h2m1m*NORM.S.DIST(_y1m,1),_A4m,_Kdr*_h2mm*NORM.S.DIST(_y2m-_sqT,1)-_Sbdm*_h2m1m*NORM.S.DIST(_y2m,1),_cfm,_Sbdm*NORM.S.DIST(-_x1m,1)+_Kdr*NORM.S.DIST(_x1m-_sqT,1),_pm,IF(_SM<=_H,_cfm,(_A1m-_A2m+_A3m-_A4m)+_cfm),(_pp-_pm)/(2*_ds*_S)) | D36: -0.000423 | E36: -2.3848 | F36: 0.0978
A37: 868.89 | B37: =LET(_S,A37,_sig,$B$4,_T,$B$5,_r,$B$6,_K,Cap,_H,Barrier,_q,q,_b,_r-_q,_sqT,_sig*SQRT(_T),_mu,(_b-0.5*_sig^2)/_sig^2,_x1,LN(_S/_K)/_sqT+(1+_mu)*_sqT,_x2,LN(_S/_H)/_sqT+(1+_mu)*_sqT,_y1,LN(_H^2/(_S*_K))/_sqT+(1+_mu)*_sqT,_y2,LN(_H/_S)/_sqT+(1+_mu)*_sqT,_Sbd,_S*EXP(-_q*_T),_Kdr,_K*EXP(-_r*_T),_h2m1,(_H/_S)^(2*(_mu+1)),_h2m,(_H/_S)^(2*_mu),_A1,_Kdr*NORM.S.DIST(_sqT-_x1,1)-_Sbd*NORM.S.DIST(-_x1,1),_A2,_Kdr*NORM.S.DIST(_sqT-_x2,1)-_Sbd*NORM.S.DIST(-_x2,1),_A3,_Kdr*_h2m*NORM.S.DIST(_y1-_sqT,1)-_Sbd*_h2m1*NORM.S.DIST(_y1,1),_A4,_Kdr*_h2m*NORM.S.DIST(_y2-_sqT,1)-_Sbd*_h2m1*NORM.S.DIST(_y2,1),_do,IF(_S<=_H,0,_A1-_A2+_A3-_A4),_cf,_Sbd*NORM.S.DIST(-_x1,1)+_Kdr*NORM.S.DIST(_x1-_sqT,1),IF(_S<=_H,_cf,_do+_cf)) | C37: =LET(_S,A37,_sig,$B$4,_T,$B$5,_r,$B$6,_K,Cap,_H,Barrier,_q,q,_ds,dS,_b,_r-_q,_sqT,_sig*SQRT(_T),_mu,(_b-0.5*_sig^2)/_sig^2,_Kdr,_K*EXP(-_r*_T),_SP,_S*(1+_ds),_Sbdp,_SP*EXP(-_q*_T),_x1p,LN(_SP/_K)/_sqT+(1+_mu)*_sqT,_x2p,LN(_SP/_H)/_sqT+(1+_mu)*_sqT,_y1p,LN(_H^2/(_SP*_K))/_sqT+(1+_mu)*_sqT,_y2p,LN(_H/_SP)/_sqT+(1+_mu)*_sqT,_h2m1p,(_H/_SP)^(2*(_mu+1)),_h2mp,(_H/_SP)^(2*_mu),_A1p,_Kdr*NORM.S.DIST(_sqT-_x1p,1)-_Sbdp*NORM.S.DIST(-_x1p,1),_A2p,_Kdr*NORM.S.DIST(_sqT-_x2p,1)-_Sbdp*NORM.S.DIST(-_x2p,1),_A3p,_Kdr*_h2mp*NORM.S.DIST(_y1p-_sqT,1)-_Sbdp*_h2m1p*NORM.S.DIST(_y1p,1),_A4p,_Kdr*_h2mp*NORM.S.DIST(_y2p-_sqT,1)-_Sbdp*_h2m1p*NORM.S.DIST(_y2p,1),_cfp,_Sbdp*NORM.S.DIST(-_x1p,1)+_Kdr*NORM.S.DIST(_x1p-_sqT,1),_pp,IF(_SP<=_H,_cfp,(_A1p-_A2p+_A3p-_A4p)+_cfp),_SM,_S*(1-_ds),_Sbdm,_SM*EXP(-_q*_T),_x1m,LN(_SM/_K)/_sqT+(1+_mu)*_sqT,_x2m,LN(_SM/_H)/_sqT+(1+_mu)*_sqT,_y1m,LN(_H^2/(_SM*_K))/_sqT+(1+_mu)*_sqT,_y2m,LN(_H/_SM)/_sqT+(1+_mu)*_sqT,_h2m1m,(_H/_SM)^(2*(_mu+1)),_h2mm,(_H/_SM)^(2*_mu),_A1m,_Kdr*NORM.S.DIST(_sqT-_x1m,1)-_Sbdm*NORM.S.DIST(-_x1m,1),_A2m,_Kdr*NORM.S.DIST(_sqT-_x2m,1)-_Sbdm*NORM.S.DIST(-_x2m,1),_A3m,_Kdr*_h2mm*NORM.S.DIST(_y1m-_sqT,1)-_Sbdm*_h2m1m*NORM.S.DIST(_y1m,1),_A4m,_Kdr*_h2mm*NORM.S.DIST(_y2m-_sqT,1)-_Sbdm*_h2m1m*NORM.S.DIST(_y2m,1),_cfm,_Sbdm*NORM.S.DIST(-_x1m,1)+_Kdr*NORM.S.DIST(_x1m-_sqT,1),_pm,IF(_SM<=_H,_cfm,(_A1m-_A2m+_A3m-_A4m)+_cfm),(_pp-_pm)/(2*_ds*_S)) | D37: -0.000434 | E37: -2.603 | F37: 0.106
... A125: 3200 | B125: =LET(_S,A125,_sig,$B$4,_T,$B$5,_r,$B$6,_K,Cap,_H,Barrier,_q,q,_b,_r-_q,_sqT,_sig*SQRT(_T),_mu,(_b-0.5*_sig^2)/_sig^2,_x1,LN(_S/_K)/_sqT+(1+_mu)*_sqT,_x2,LN(_S/_H)/_sqT+(1+_mu)*_sqT,_y1,LN(_H^2/(_S*_K))/_sqT+(1+_mu)*_sqT,_y2,LN(_H/_S)/_sqT+(1+_mu)*_sqT,_Sbd,_S*EXP(-_q*_T),_Kdr,_K*EXP(-_r*_T),_h2m1,(_H/_S)^(2*(_mu+1)),_h2m,(_H/_S)^(2*_mu),_A1,_Kdr*NORM.S.DIST(_sqT-_x1,1)-_Sbd*NORM.S.DIST(-_x1,1),_A2,_Kdr*NORM.S.DIST(_sqT-_x2,1)-_Sbd*NORM.S.DIST(-_x2,1),_A3,_Kdr*_h2m*NORM.S.DIST(_y1-_sqT,1)-_Sbd*_h2m1*NORM.S.DIST(_y1,1),_A4,_Kdr*_h2m*NORM.S.DIST(_y2-_sqT,1)-_Sbd*_h2m1*NORM.S.DIST(_y2,1),_do,IF(_S<=_H,0,_A1-_A2+_A3-_A4),_cf,_Sbd*NORM.S.DIST(-_x1,1)+_Kdr*NORM.S.DIST(_x1-_sqT,1),IF(_S<=_H,_cf,_do+_cf)) | C125: =LET(_S,A125,_sig,$B$4,_T,$B$5,_r,$B$6,_K,Cap,_H,Barrier,_q,q,_ds,dS,_b,_r-_q,_sqT,_sig*SQRT(_T),_mu,(_b-0.5*_sig^2)/_sig^2,_Kdr,_K*EXP(-_r*_T),_SP,_S*(1+_ds),_Sbdp,_SP*EXP(-_q*_T),_x1p,LN(_SP/_K)/_sqT+(1+_mu)*_sqT,_x2p,LN(_SP/_H)/_sqT+(1+_mu)*_sqT,_y1p,LN(_H^2/(_SP*_K))/_sqT+(1+_mu)*_sqT,_y2p,LN(_H/_SP)/_sqT+(1+_mu)*_sqT,_h2m1p,(_H/_SP)^(2*(_mu+1)),_h2mp,(_H/_SP)^(2*_mu),_A1p,_Kdr*NORM.S.DIST(_sqT-_x1p,1)-_Sbdp*NORM.S.DIST(-_x1p,1),_A2p,_Kdr*NORM.S.DIST(_sqT-_x2p,1)-_Sbdp*NORM.S.DIST(-_x2p,1),_A3p,_Kdr*_h2mp*NORM.S.DIST(_y1p-_sqT,1)-_Sbdp*_h2m1p*NORM.S.DIST(_y1p,1),_A4p,_Kdr*_h2mp*NORM.S.DIST(_y2p-_sqT,1)-_Sbdp*_h2m1p*NORM.S.DIST(_y2p,1),_cfp,_Sbdp*NORM.S.DIST(-_x1p,1)+_Kdr*NORM.S.DIST(_x1p-_sqT,1),_pp,IF(_SP<=_H,_cfp,(_A1p-_A2p+_A3p-_A4p)+_cfp),_SM,_S*(1-_ds),_Sbdm,_SM*EXP(-_q*_T),_x1m,LN(_SM/_K)/_sqT+(1+_mu)*_sqT,_x2m,LN(_SM/_H)/_sqT+(1+_mu)*_sqT,_y1m,LN(_H^2/(_SM*_K))/_sqT+(1+_mu)*_sqT,_y2m,LN(_H/_SM)/_sqT+(1+_mu)*_sqT,_h2m1m,(_H/_SM)^(2*(_mu+1)),_h2mm,(_H/_SM)^(2*_mu),_A1m,_Kdr*NORM.S.DIST(_sqT-_x1m,1)-_Sbdm*NORM.S.DIST(-_x1m,1),_A2m,_Kdr*NORM.S.DIST(_sqT-_x2m,1)-_Sbdm*NORM.S.DIST(-_x2m,1),_A3m,_Kdr*_h2mm*NORM.S.DIST(_y1m-_sqT,1)-_Sbdm*_h2m1m*NORM.S.DIST(_y1m,1),_A4m,_Kdr*_h2mm*NORM.S.DIST(_y2m-_sqT,1)-_Sbdm*_h2m1m*NORM.S.DIST(_y2m,1),_cfm,_Sbdm*NORM.S.DIST(-_x1m,1)+_Kdr*NORM.S.DIST(_x1m-_sqT,1),_pm,IF(_SM<=_H,_cfm,(_A1m-_A2m+_A3m-_A4m)+_cfm),(_pp-_pm)/(2*_ds*_S)) | D125: -0.000107 | E125: -8.706 | F125: 0.3847

Sheet P2_TaskVII_Rep
A1: Task VII -- Daily Replicating Portfolio (RR closed-form)
A2: Columns B-E: live formulas pulling from Data_Stock / Data_Svensson. Columns F-G: live Haug RR LET formulas (Excel 365). Columns H-J: live arithmetic on F-G. Press Ctrl+Alt+F9 to recalculate.
A3: Date | B3: S (EUR) | C3: sigma | D3: T_rem (yr) | E3: r | F3: Price (RR) | G3: Delta (RR) | H3: Equity (EUR) | I3: Bond (EUR) | J3: Eq Fraction
A4: =Data_Stock!A4 | B4: =Data_Stock!B4 | C4: =Data_Stock!C4 | D4: =Data_Svensson!H4 | E4: =Data_Svensson!I4 | F4: =LET(_S,B4,_sig,C4,_T,D4,_r,E4,_K,Cap,_H,Barrier,_q,q,_b,_r-_q,_sqT,_sig*SQRT(_T),_mu,(_b-0.5*_sig^2)/_sig^2,_x1,LN(_S/_K)/_sqT+(1+_mu)*_sqT,_x2,LN(_S/_H)/_sqT+(1+_mu)*_sqT,_y1,LN(_H^2/(_S*_K))/_sqT+(1+_mu)*_sqT,_y2,LN(_H/_S)/_sqT+(1+_mu)*_sqT,_Sbd,_S*EXP(-_q*_T),_Kdr,_K*EXP(-_r*_T),_h2m1,(_H/_S)^(2*(_mu+1)),_h2m,(_H/_S)^(2*_mu),_A1,_Kdr*NORM.S.DIST(_sqT-_x1,1)-_Sbd*NORM.S.DIST(-_x1,1),_A2,_Kdr*NORM.S.DIST(_sqT-_x2,1)-_Sbd*NORM.S.DIST(-_x2,1),_A3,_Kdr*_h2m*NORM.S.DIST(_y1-_sqT,1)-_Sbd*_h2m1*NORM.S.DIST(_y1,1),_A4,_Kdr*_h2m*NORM.S.DIST(_y2-_sqT,1)-_Sbd*_h2m1*NORM.S.DIST(_y2,1),_do,IF(_S<=_H,0,_A1-_A2+_A3-_A4),_cf,_Sbd*NORM.S.DIST(-_x1,1)+_Kdr*NORM.S.DIST(_x1-_sqT,1),IF(_S<=_H,_cf,_do+_cf)) | G4: =LET(_S,B4,_sig,C4,_T,D4,_r,E4,_K,Cap,_H,Barrier,_q,q,_ds,dS,_b,_r-_q,_sqT,_sig*SQRT(_T),_mu,(_b-0.5*_sig^2)/_sig^2,_Kdr,_K*EXP(-_r*_T),_SP,_S*(1+_ds),_Sbdp,_SP*EXP(-_q*_T),_x1p,LN(_SP/_K)/_sqT+(1+_mu)*_sqT,_x2p,LN(_SP/_H)/_sqT+(1+_mu)*_sqT,_y1p,LN(_H^2/(_SP*_K))/_sqT+(1+_mu)*_sqT,_y2p,LN(_H/_SP)/_sqT+(1+_mu)*_sqT,_h2m1p,(_H/_SP)^(2*(_mu+1)),_h2mp,(_H/_SP)^(2*_mu),_A1p,_Kdr*NORM.S.DIST(_sqT-_x1p,1)-_Sbdp*NORM.S.DIST(-_x1p,1),_A2p,_Kdr*NORM.S.DIST(_sqT-_x2p,1)-_Sbdp*NORM.S.DIST(-_x2p,1),_A3p,_Kdr*_h2mp*NORM.S.DIST(_y1p-_sqT,1)-_Sbdp*_h2m1p*NORM.S.DIST(_y1p,1),_A4p,_Kdr*_h2mp*NORM.S.DIST(_y2p-_sqT,1)-_Sbdp*_h2m1p*NORM.S.DIST(_y2p,1),_cfp,_Sbdp*NORM.S.DIST(-_x1p,1)+_Kdr*NORM.S.DIST(_x1p-_sqT,1),_pp,IF(_SP<=_H,_cfp,(_A1p-_A2p+_A3p-_A4p)+_cfp),_SM,_S*(1-_ds),_Sbdm,_SM*EXP(-_q*_T),_x1m,LN(_SM/_K)/_sqT+(1+_mu)*_sqT,_x2m,LN(_SM/_H)/_sqT+(1+_mu)*_sqT,_y1m,LN(_H^2/(_SM*_K))/_sqT+(1+_mu)*_sqT,_y2m,LN(_H/_SM)/_sqT+(1+_mu)*_sqT,_h2m1m,(_H/_SM)^(2*(_mu+1)),_h2mm,(_H/_SM)^(2*_mu),_A1m,_Kdr*NORM.S.DIST(_sqT-_x1m,1)-_Sbdm*NORM.S.DIST(-_x1m,1),_A2m,_Kdr*NORM.S.DIST(_sqT-_x2m,1)-_Sbdm*NORM.S.DIST(-_x2m,1),_A3m,_Kdr*_h2mm*NORM.S.DIST(_y1m-_sqT,1)-_Sbdm*_h2m1m*NORM.S.DIST(_y1m,1),_A4m,_Kdr*_h2mm*NORM.S.DIST(_y2m-_sqT,1)-_Sbdm*_h2m1m*NORM.S.DIST(_y2m,1),_cfm,_Sbdm*NORM.S.DIST(-_x1m,1)+_Kdr*NORM.S.DIST(_x1m-_sqT,1),_pm,IF(_SM<=_H,_cfm,(_A1m-_A2m+_A3m-_A4m)+_cfm),(_pp-_pm)/(2*_ds*_S)) | H4: =G4*B4 | I4: =F4-H4 | J4: =IF(F4>0,H4/F4,0)
A5: =Data_Stock!A5 | B5: =Data_Stock!B5 | C5: =Data_Stock!C5 | D5: =Data_Svensson!H5 | E5: =Data_Svensson!I5 | F5: =LET(_S,B5,_sig,C5,_T,D5,_r,E5,_K,Cap,_H,Barrier,_q,q,_b,_r-_q,_sqT,_sig*SQRT(_T),_mu,(_b-0.5*_sig^2)/_sig^2,_x1,LN(_S/_K)/_sqT+(1+_mu)*_sqT,_x2,LN(_S/_H)/_sqT+(1+_mu)*_sqT,_y1,LN(_H^2/(_S*_K))/_sqT+(1+_mu)*_sqT,_y2,LN(_H/_S)/_sqT+(1+_mu)*_sqT,_Sbd,_S*EXP(-_q*_T),_Kdr,_K*EXP(-_r*_T),_h2m1,(_H/_S)^(2*(_mu+1)),_h2m,(_H/_S)^(2*_mu),_A1,_Kdr*NORM.S.DIST(_sqT-_x1,1)-_Sbd*NORM.S.DIST(-_x1,1),_A2,_Kdr*NORM.S.DIST(_sqT-_x2,1)-_Sbd*NORM.S.DIST(-_x2,1),_A3,_Kdr*_h2m*NORM.S.DIST(_y1-_sqT,1)-_Sbd*_h2m1*NORM.S.DIST(_y1,1),_A4,_Kdr*_h2m*NORM.S.DIST(_y2-_sqT,1)-_Sbd*_h2m1*NORM.S.DIST(_y2,1),_do,IF(_S<=_H,0,_A1-_A2+_A3-_A4),_cf,_Sbd*NORM.S.DIST(-_x1,1)+_Kdr*NORM.S.DIST(_x1-_sqT,1),IF(_S<=_H,_cf,_do+_cf)) | G5: =LET(_S,B5,_sig,C5,_T,D5,_r,E5,_K,Cap,_H,Barrier,_q,q,_ds,dS,_b,_r-_q,_sqT,_sig*SQRT(_T),_mu,(_b-0.5*_sig^2)/_sig^2,_Kdr,_K*EXP(-_r*_T),_SP,_S*(1+_ds),_Sbdp,_SP*EXP(-_q*_T),_x1p,LN(_SP/_K)/_sqT+(1+_mu)*_sqT,_x2p,LN(_SP/_H)/_sqT+(1+_mu)*_sqT,_y1p,LN(_H^2/(_SP*_K))/_sqT+(1+_mu)*_sqT,_y2p,LN(_H/_SP)/_sqT+(1+_mu)*_sqT,_h2m1p,(_H/_SP)^(2*(_mu+1)),_h2mp,(_H/_SP)^(2*_mu),_A1p,_Kdr*NORM.S.DIST(_sqT-_x1p,1)-_Sbdp*NORM.S.DIST(-_x1p,1),_A2p,_Kdr*NORM.S.DIST(_sqT-_x2p,1)-_Sbdp*NORM.S.DIST(-_x2p,1),_A3p,_Kdr*_h2mp*NORM.S.DIST(_y1p-_sqT,1)-_Sbdp*_h2m1p*NORM.S.DIST(_y1p,1),_A4p,_Kdr*_h2mp*NORM.S.DIST(_y2p-_sqT,1)-_Sbdp*_h2m1p*NORM.S.DIST(_y2p,1),_cfp,_Sbdp*NORM.S.DIST(-_x1p,1)+_Kdr*NORM.S.DIST(_x1p-_sqT,1),_pp,IF(_SP<=_H,_cfp,(_A1p-_A2p+_A3p-_A4p)+_cfp),_SM,_S*(1-_ds),_Sbdm,_SM*EXP(-_q*_T),_x1m,LN(_SM/_K)/_sqT+(1+_mu)*_sqT,_x2m,LN(_SM/_H)/_sqT+(1+_mu)*_sqT,_y1m,LN(_H^2/(_SM*_K))/_sqT+(1+_mu)*_sqT,_y2m,LN(_H/_SM)/_sqT+(1+_mu)*_sqT,_h2m1m,(_H/_SM)^(2*(_mu+1)),_h2mm,(_H/_SM)^(2*_mu),_A1m,_Kdr*NORM.S.DIST(_sqT-_x1m,1)-_Sbdm*NORM.S.DIST(-_x1m,1),_A2m,_Kdr*NORM.S.DIST(_sqT-_x2m,1)-_Sbdm*NORM.S.DIST(-_x2m,1),_A3m,_Kdr*_h2mm*NORM.S.DIST(_y1m-_sqT,1)-_Sbdm*_h2m1m*NORM.S.DIST(_y1m,1),_A4m,_Kdr*_h2mm*NORM.S.DIST(_y2m-_sqT,1)-_Sbdm*_h2m1m*NORM.S.DIST(_y2m,1),_cfm,_Sbdm*NORM.S.DIST(-_x1m,1)+_Kdr*NORM.S.DIST(_x1m-_sqT,1),_pm,IF(_SM<=_H,_cfm,(_A1m-_A2m+_A3m-_A4m)+_cfm),(_pp-_pm)/(2*_ds*_S)) | H5: =G5*B5 | I5: =F5-H5 | J5: =IF(F5>0,H5/F5,0)
